Workbook

Sheet 报名明细
A1: 岗位数量 | B1: 企业名称 | C1: 企业简介 | D1: 招聘岗位 | E1: 招聘人数 | F1: 学历 | G1: 岗位职责 | H1: 薪资情况 | I1: 标题拼接 | J1: 岗位长度 | K1: 岗位长度要求 | L1: 岗位长度截取 | M1: 专业 | N1: 专业字数 | O1: 专业个数
A2: =COUNTIF(B:B,B2) -> 4 | B2: 上海光通信有限公司 | C2: 上海光通信有限公司（英文名ShanghaiGTXSemiconductorCo.,Ltd，下称“GTX”），成立于1988年，于2022年初转型进入集成电路制造领域。 | D2: 仓储助理专员 | E2: 10 | F2: 大专 | G2: 工作职责1)根据规程，执行公司各种物资运输安排、管理及监控；2)执行物资仓储管理，保证物资有序账目清晰。任职要求1)大专及以上学历，物流、仓储等相关专业；2)具备良好的沟通能力和团队合作精神，具备独立工作、分析和解决问题的能力，良好的中英文读写说能力。 | H2: 月薪：5K-7K | I2: =_xlfn.CONCAT(D2,"（学历：",F2," 专业要求：",IF(ISBLANK(M2),"无",M2),"）") -> 仓储助理专员（学历：大专 专业要求：无） | J2: =LEN(G2) -> 126 | K2: =_xlfn.XLOOKUP(A2,长度要求!A:A,长度要求!E:E) -> 500 | L2: =IF(J2<K2,G2,LEFT(G2,K2)&"……") -> 工作职责1)根据规程，执行公司各种物资运输安排、管理及监控；2)执行物资仓储管理，保证物资有序账目清晰。任职要求1)大专及以上学历，物流、仓储等相关专业；2)具备良好的沟通能力和团队合作精神，具备独立工作、分析和解决问题的能力，良好的中英文读写说能力。 | N2: =LEN(M2) -> 0 | O2: =IF(ISBLANK(M2),0,COUNTA(_xlfn.TEXTSPLIT(M2,","))) -> 0
A3: =COUNTIF(B:B,B3) -> 6 | B3: 上海新皋实业有限公司 | C3: 新皋实业成立于2013年初，总部位于上海虹桥机场毗邻的明谷科技园，公司在智能家居领域率先投入智能家居控制系统的项目研发、生产及销售。获得软件专利著作权十多项，企业获得国家商标局认证商标：《新皋》《XINGAO》《艾登堡》《ATNBO》等品牌，并推出真正适合国内外用户的智能影音系列产品。自主研发新皋XINGAO智能影院中控系统及艾登堡ATNBO家庭影院系列产品,深受行业专业人士好评。新皋实业是上海闵行区就业促进中心审核认定的大学生实习基地，常年招收在校大学生实习实践，上海闵行地区户籍大学生或闵行地区高校学生优先录取，实习享受上海市闵行区人社局补贴。 | D3: 设计，UI设计，效果图设计 | E3: 5 | F3: 大专 | G3: 工作内容：企业设计类工作，主要内容协助领导UI设计工作。招聘条件：有相关工作经验者优先；1、熟悉办公软件操作，具备良好的文字表达能力；2、熟练UI设计软件。公司从事智能家居及智能私人影院技术研发及硬件生产，招聘在校大学生实习实践，对智能家居，私人影院设备产品感兴趣者，实习生学员公司各岗位培养。实习期间成绩优秀者，毕业学年转正为企业员工，签定劳动合同，享受企业员工一切待遇。上海新皋实业有限公司是上海闵行区人社局及财政局审核认定的大学生实习实训基地。 | H3: 日薪：80-180/天 | I3: =_xlfn.CONCAT(D3,"（学历：",F3," 专业要求：",IF(ISBLANK(M3),"无",M3),"）") -> 设计，UI设计，效果图设计（学历：大专 专业要求：无） | J3: =LEN(G3) -> 225 | K3: =_xlfn.XLOOKUP(A3,长度要求!A:A,长度要求!E:E) -> 500 | L3: =IF(J3<K3,G3,LEFT(G3,K3)&"……") -> 工作内容：企业设计类工作，主要内容协助领导UI设计工作。招聘条件：有相关工作经验者优先；1、熟悉办公软件操作，具备良好的文字表达能力；2、熟练UI设计软件。公司从事智能家居及智能私人影院技术研发及硬件生产，招聘在校大学生实习实践，对智能家居，私人影院设备产品感兴趣者，实习生学员公司各岗位培养。实习期间成绩优秀者，毕业学年转正为企业员工，签定劳动合同，享受企业员工一切待遇。上海新皋实业有限公司是上海闵行区人社局及财政局审核认定的大学生实习实训基地。 | N3: =LEN(M3) -> 0 | O3: =IF(ISBLANK(M3),0,COUNTA(_xlfn.TEXTSPLIT(M3,","))) -> 0
A4: =COUNTIF(B:B,B4) -> 6 | B4: 上海新皋实业有限公司 | C4: 新皋实业成立于2013年初，总部位于上海虹桥机场毗邻的明谷科技园，公司在智能家居领域率先投入智能家居控制系统的项目研发、生产及销售。获得软件专利著作权十多项，企业获得国家商标局认证商标：《新皋》《XINGAO》《艾登堡》《ATNBO》等品牌，并推出真正适合国内外用户的智能影音系列产品。自主研发新皋XINGAO智能影院中控系统及艾登堡ATNBO家庭影院系列产品,深受行业专业人士好评。新皋实业是上海闵行区就业促进中心审核认定的大学生实习基地，常年招收在校大学生实习实践，上海闵行地区户籍大学生或闵行地区高校学生优先录取，实习享受上海市闵行区人社局补贴。 | D4: 物联网技术助理 | E4: 3 | F4: 初中及以下 | G4: 我司是上海市人社局批准大学生实习基地，闵行区户籍实习生可以享受政府津贴，名额有限。公司从事智能家居及智能私人影院技术研发及硬件设备调试，招聘智能家居行业相关专业的在校大学生实习实践，要求物联网技术或电子及机电专业学生，具备弱电接线动手能力，对智能家居，私人影院设备安装调试感兴趣者，实习生学员公司提供技术培训。实习期间成绩优秀者，毕业学年转正为企业员工，签定劳动合同，享受企业员工一切待遇。优秀学员企业另外增加岗位津贴。面试证件：身份证；学信网个人资料；公司地址：上海市闵行区中春路7001号（明谷科技园）B栋415。公交路线：地铁9号线中春路站（2号口）出来沿着中春路骑行（10分钟）到达明谷科技园东大门，公司在东门左边进口处。 | H4: 日薪：80-150/天 | I4: =_xlfn.CONCAT(D4,"（学历：",F4," 专业要求：",IF(ISBLANK(M4),"无",M4),"）") -> 物联网技术助理（学历：初中及以下 专业要求：微电子技术,微电子学与固体电子学,微电子科学与工程） | J4: =LEN(G4) -> 315 | K4: =_xlfn.XLOOKUP(A4,长度要求!A:A,长度要求!E:E) -> 500 | L4: =IF(J4<K4,G4,LEFT(G4,K4)&"……") -> 我司是上海市人社局批准大学生实习基地，闵行区户籍实习生可以享受政府津贴，名额有限。公司从事智能家居及智能私人影院技术研发及硬件设备调试，招聘智能家居行业相关专业的在校大学生实习实践，要求物联网技术或电子及机电专业学生，具备弱电接线动手能力，对智能家居，私人影院设备安装调试感兴趣者，实习生学员公司提供技术培训。实习期间成绩优秀者，毕业学年转正为企业员工，签定劳动合同，享受企业员工一切待遇。优秀学员企业另外增加岗位津贴。面试证件：身份证；学信网个人资料；公司地址：上海市闵行区中春路7001号（明谷科技园）B栋415。公交路线：地铁9号线中春路站（2号口）出来沿着中春路骑行（10分钟）到达明谷科技园东大门，公司在东门左边进口处。 | M4: 微电子技术,微电子学与固体电子学,微电子科学与工程 | N4: =LEN(M4) -> 25 | O4: =IF(ISBLANK(M4),0,COUNTA(_xlfn.TEXTSPLIT(M4,","))) -> 3
A5: =COUNTIF(B:B,B5) -> 2 | B5: 上海德辰汽车销售有限公司 | C5: 上海德辰汽车销售公司是北方一大型汽车经销商集团在上海新投资创立的一汽大众奥迪品牌4S店。超越了传统豪华汽车4S店的概念，实际具备品牌体验、车型展示、新车销售、售后服务、二手车置换等多种功能，完备的设施以及周到的服务一应俱全，体现出国际豪华品牌全球统一的服务水准。该城市展厅坐落于闵行区颛桥地区（颛兴东路1280弄3号）。地铁、轻轨均可到达，交通便捷。地址：颛兴东路1280弄3号。总占地面积11455平方米。上下共有三层，展厅面积4168平方米，销售展示分两层，有超过多个标准汽车展位，大厅设有人性化的自动扶梯；屋顶设置顶楼停车厂，日接待能力超过100台。简洁明快的建筑风格，落地玻璃和透明天窗的结合使整个展厅最大限度地充满阳光和自然气息，充分体现了人性与科技的完美结合，展现奥迪品牌的超凡卓越和豪华尊贵，修理车间面积7287平方米，共有多个汽车维修工位，技术人员有40人，分为机修、电工、钣金、喷漆区，布局合理，设备先进。突出强调“买车修车到德辰，诚信舒心更放心”的服务理念。也是每个德辰员工的座右铭。我们以完善的硬件设施、周到的人性化服务迎接您的光临。背景介绍上海德辰的股东旗下共拥有多家4S店，其中在长春、嘉兴、宁波销售一汽奥迪、一汽马自达、一汽丰田等知名品牌汽车。企业文化上海德辰奉行“务实、诚信、进取、激情、团队精神、服务意识”的企业文化；在选人、用人、育人上：以具竞争力的薪酬吸引人才、以完善的培训体系培养人才，以强烈的业绩导向、快速的晋升和广阔的发展空间开发人才。 | D5: 机电实习生 | E5: 2 | F5: 中专/技校 | G5: 具有一定的汽车理论知识和汽车维修知识，具有较强的动手能力、语言表达能力、独立解决问题的能力、汽车工艺学习及钻研能力 | H5: 日薪：80-150/天 | I5: =_xlfn.CONCAT(D5,"（学历：",F5," 专业要求：",IF(ISBLANK(M5),"无",M5),"）") -> 机电实习生（学历：中专/技校 专业要求：汽车检测与维修技术,新能源汽车技术,汽车运用与维修技术,汽车车身维修技术,新能源汽车运用与维修,汽车制造类,汽车服务工程,汽车维修工程教育,新能源汽车工程） | J5: =LEN(G5) -> 57 | K5: =_xlfn.XLOOKUP(A5,长度要求!A:A,长度要求!E:E) -> 500 | L5: =IF(J5<K5,G5,LEFT(G5,K5)&"……") -> 具有一定的汽车理论知识和汽车维修知识，具有较强的动手能力、语言表达能力、独立解决问题的能力、汽车工艺学习及钻研能力 | M5: 汽车检测与维修技术,新能源汽车技术,汽车运用与维修技术,汽车车身维修技术,新能源汽车运用与维修,汽车制造类,汽车服务工程,汽车维修工程教育,新能源汽车工程 | N5: =LEN(M5) -> 77 | O5: =IF(ISBLANK(M5),0,COUNTA(_xlfn.TEXTSPLIT(M5,","))) -> 9
A6: =COUNTIF(B:B,B6) -> 1 | B6: 上海市黄浦区西凌第一幼儿园 | C6: 西凌第一幼儿园是一所上海市示范性幼儿园、上海市文明单位。地处黄浦区西藏南路，园内幼儿活动场地充裕，环境优美，四季绿化常青，阳光充足，是“上海市花园单位”。我园积极探索围棋与游戏融合的探索，秉持“以人为本，民主和谐，快乐发展”办园宗旨和“以棋养德、以棋怡情、以棋明理、以棋启智”的教育理念，深受幼儿与家长的喜欢。西凌第一幼儿园已成为孩子们游戏、学习、生活的乐园。 | D6: 保育员 | E6: 5 | F6: 初中及以下 | G6: 具有良好师德，爱孩子，有正确的儿童观具备保育专业知识与技能 | H6: 月薪：3K-5K | I6: =_xlfn.CONCAT(D6,"（学历：",F6," 专业要求：",IF(ISBLANK(M6),"无",M6),"）") -> 保育员（学历：初中及以下 专业要求：学前教育,卫生教育） | J6: =LEN(G6) -> 29 | K6: =_xlfn.XLOOKUP(A6,长度要求!A:A,长度要求!E:E) -> 500 | L6: =IF(J6<K6,G6,LEFT(G6,K6)&"……") -> 具有良好师德，爱孩子，有正确的儿童观具备保育专业知识与技能 | M6: 学前教育,卫生教育 | N6: =LEN(M6) -> 9 | O6: =IF(ISBLANK(M6),0,COUNTA(_xlfn.TEXTSPLIT(M6,","))) -> 2
A7: =COUNTIF(B:B,B7) -> 6 | B7: 上海新皋实业有限公司 | C7: 新皋实业成立于2013年初，总部位于上海虹桥机场毗邻的明谷科技园，公司在智能家居领域率先投入智能家居控制系统的项目研发、生产及销售。获得软件专利著作权十多项，企业获得国家商标局认证商标：《新皋》《XINGAO》《艾登堡》《ATNBO》等品牌，并推出真正适合国内外用户的智能影音系列产品。自主研发新皋XINGAO智能影院中控系统及艾登堡ATNBO家庭影院系列产品,深受行业专业人士好评。新皋实业是上海闵行区就业促进中心审核认定的大学生实习基地，常年招收在校大学生实习实践，上海闵行地区户籍大学生或闵行地区高校学生优先录取，实习享受上海市闵行区人社局补贴。 | D7: 新媒体运营 | E7: 4 | F7: 初中及以下 | G7: 工作内容负责公司多媒体渠道（包括但不限于微信公众号、抖音、微博等）的运营管理和内容策划。通过策划和执行，提升公司多媒体渠道的曝光度和用户粘性。主要职责：1、负责公司多媒体渠道的运营管理和内容策划，包括但不限于制定并执行渠道内容计划、跟踪和优化渠道运营效果、策划并执行创意等；2、撰写、编辑、发布公司公众号多媒体内容，提升内容质量和创意，以满足用户需求和公司需求；3、根据公司业务需求，制定并执行多媒体渠道的定期更新和升级策略，提升公司多媒体品牌形象和用户黏性；4、定期汇报公司多媒体渠道运营效果，提供数据驱动的改进建议，以优化公司多媒体运营策略；5、与其他部门的沟通和协作，包括但不限于与视频拍摄团队、设计师等合作，提升公司多媒体内容质量和用户体验。招聘条件多媒体运营专业，大专及以上学历，具备较强的项目管理能力和团队协作能力；1、熟悉新媒体渠道，具有一定的内容策划和创意能力，善于分析数据驱动问题；2、具有较强的沟通协调能力，能够与不同部门进行有效沟通和协作；3、具有较强的逻辑思维能力，能够独立思考和解决问题；4、熟练掌握公司多媒体运营流程和方法，了解公司业务需求。具有视频拍摄剪辑编辑能力。熟练OFFICE和PS、PR软件。上海闵行地区户籍大学生；或上海：交大、华师大、电机学院、东海大学大专院校学生享受本地区政策补贴扶持。闵行区大学生投递简历优先录用。公司地址：上海闵行区中春路7001号明谷科技园B栋415 | H7: 日薪：80-180/天 | I7: =_xlfn.CONCAT(D7,"（学历：",F7," 专业要求：",IF(ISBLANK(M7),"无",M7),"）") -> 新媒体运营（学历：初中及以下 专业要求：无） | J7: =LEN(G7) -> 608 | K7: =_xlfn.XLOOKUP(A7,长度要求!A:A,长度要求!E:E) -> 500 | L7: =IF(J7<K7,G7,LEFT(G7,K7)&"……") -> 工作内容负责公司多媒体渠道（包括但不限于微信公众号、抖音、微博等）的运营管理和内容策划。通过策划和执行，提升公司多媒体渠道的曝光度和用户粘性。主要职责：1、负责公司多媒体渠道的运营管理和内容策划，包括但不限于制定并执行渠道内容计划、跟踪和优化渠道运营效果、策划并执行创意等；2、撰写、编辑、发布公司公众号多媒体内容，提升内容质量和创意，以满足用户需求和公司需求；3、根据公司业务需求，制定并执行多媒体渠道的定期更新和升级策略，提升公司多媒体品牌形象和用户黏性；4、定期汇报公司多媒体渠道运营效果，提供数据驱动的改进建议，以优化公司多媒体运营策略；5、与其他部门的沟通和协作，包括但不限于与视频拍摄团队、设计师等合作，提升公司多媒体内容质量和用户体验。招聘条件多媒体运营专业，大专及以上学历，具备较强的项目管理能力和团队协作能力；1、熟悉新媒体渠道，具有一定的内容策划和创意能力，善于分析数据驱动问题；2、具有较强的沟通协调能力，能够与不同部门进行有效沟通和协作；3、具有较强的逻辑思维能力，能够独立思考和解决问题；4、熟练掌握公司多媒体运营流程和方法，了解公司业务需求。具有视频拍摄剪辑编辑能力。熟练…… | N7: =LEN(M7) -> 0 | O7: =IF(ISBLANK(M7),0,COUNTA(_xlfn.TEXTSPLIT(M7,","))) -> 0
A8: =COUNTIF(B:B,B8) -> 6 | B8: 上海新皋实业有限公司 | C8: 新皋实业成立于2013年初，总部位于上海虹桥机场毗邻的明谷科技园，公司在智能家居领域率先投入智能家居控制系统的项目研发、生产及销售。获得软件专利著作权十多项，企业获得国家商标局认证商标：《新皋》《XINGAO》《艾登堡》《ATNBO》等品牌，并推出真正适合国内外用户的智能影音系列产品。自主研发新皋XINGAO智能影院中控系统及艾登堡ATNBO家庭影院系列产品,深受行业专业人士好评。新皋实业是上海闵行区就业促进中心审核认定的大学生实习基地，常年招收在校大学生实习实践，上海闵行地区户籍大学生或闵行地区高校学生优先录取，实习享受上海市闵行区人社局补贴。 | D8: 技术调试普工 | E8: 3 | F8: 大专 | G8: 工作内容负责生产电子产品组装+装配+测试等简单工作。1.通过岗位技能培训后，对电子元器件进行装配；2.对产品进行外观方面的品质检查；3.每日下班前，保持台面和工具的清洁；招聘条件：文化程度：中专及以上学历；机电电子专业、物联网专业或微电子专业；有电子产品组装能力；能手工焊接工，会使用小型电动工具设备，熟练的动手能力。身体健康、工作认真负责，吃苦耐劳。 | H8: 日薪：80-150/天 | I8: =_xlfn.CONCAT(D8,"（学历：",F8," 专业要求：",IF(ISBLANK(M8),"无",M8),"）") -> 技术调试普工（学历：大专 专业要求：无） | J8: =LEN(G8) -> 176 | K8: =_xlfn.XLOOKUP(A8,长度要求!A:A,长度要求!E:E) -> 500 | L8: =IF(J8<K8,G8,LEFT(G8,K8)&"……") -> 工作内容负责生产电子产品组装+装配+测试等简单工作。1.通过岗位技能培训后，对电子元器件进行装配；2.对产品进行外观方面的品质检查；3.每日下班前，保持台面和工具的清洁；招聘条件：文化程度：中专及以上学历；机电电子专业、物联网专业或微电子专业；有电子产品组装能力；能手工焊接工，会使用小型电动工具设备，熟练的动手能力。身体健康、工作认真负责，吃苦耐劳。 | N8: =LEN(M8) -> 0 | O8: =IF(ISBLANK(M8),0,COUNTA(_xlfn.TEXTSPLIT(M8,","))) -> 0
A9: =COUNTIF(B:B,B9) -> 6 | B9: 上海新皋实业有限公司 | C9: 新皋实业成立于2013年初，总部位于上海虹桥机场毗邻的明谷科技园，公司在智能家居领域率先投入智能家居控制系统的项目研发、生产及销售。获得软件专利著作权十多项，企业获得国家商标局认证商标：《新皋》《XINGAO》《艾登堡》《ATNBO》等品牌，并推出真正适合国内外用户的智能影音系列产品。自主研发新皋XINGAO智能影院中控系统及艾登堡ATNBO家庭影院系列产品,深受行业专业人士好评。新皋实业是上海闵行区就业促进中心审核认定的大学生实习基地，常年招收在校大学生实习实践，上海闵行地区户籍大学生或闵行地区高校学生优先录取，实习享受上海市闵行区人社局补贴。 | D9: 办公室文员(人事助理） | E9: 2 | F9: 大专 | G9: 工作内容：负责办公室日常运营和维护，处理各类文件及档案，负责公司会议前准备工作：负责协助部门负责人完成人事行政辅助类工作，包括但不限于来客来访接待、整理文件等；招聘条件：不限工作经验，有相关工作经验者优先；1、熟悉办公软件操作，具备良好的文字表达能力；2、具备良好的组织协调能力和团队合作意识；3、具有较强的沟通能力和抗压能力，能够适应工作中的挑战；4、有较强的责任心和事业心， | H9: 日薪：80-150/天 | I9: =_xlfn.CONCAT(D9,"（学历：",F9," 专业要求：",IF(ISBLANK(M9),"无",M9),"）") -> 办公室文员(人事助理）（学历：大专 专业要求：无） | J9: =LEN(G9) -> 189 | K9: =_xlfn.XLOOKUP(A9,长度要求!A:A,长度要求!E:E) -> 500 | L9: =IF(J9<K9,G9,LEFT(G9,K9)&"……") -> 工作内容：负责办公室日常运营和维护，处理各类文件及档案，负责公司会议前准备工作：负责协助部门负责人完成人事行政辅助类工作，包括但不限于来客来访接待、整理文件等；招聘条件：不限工作经验，有相关工作经验者优先；1、熟悉办公软件操作，具备良好的文字表达能力；2、具备良好的组织协调能力和团队合作意识；3、具有较强的沟通能力和抗压能力，能够适应工作中的挑战；4、有较强的责任心和事业心， | N9: =LEN(M9) -> 0 | O9: =IF(ISBLANK(M9),0,COUNTA(_xlfn.TEXTSPLIT(M9,","))) -> 0
A10: =COUNTIF(B:B,B10) -> 6 | B10: 上海新皋实业有限公司 | C10: 新皋实业成立于2013年初，总部位于上海虹桥机场毗邻的明谷科技园，公司在智能家居领域率先投入智能家居控制系统的项目研发、生产及销售。获得软件专利著作权十多项，企业获得国家商标局认证商标：《新皋》《XINGAO》《艾登堡》《ATNBO》等品牌，并推出真正适合国内外用户的智能影音系列产品。自主研发新皋XINGAO智能影院中控系统及艾登堡ATNBO家庭影院系列产品,深受行业专业人士好评。新皋实业是上海闵行区就业促进中心审核认定的大学生实习基地，常年招收在校大学生实习实践，上海闵行地区户籍大学生或闵行地区高校学生优先录取，实习享受上海市闵行区人社局补贴。 | D10: 电商运营 (电商客服) | E10: 5 | F10: 大专 | G10: 工作内容：1、负责店铺日常运营，包括商品上架、售后处理、物流跟踪等；日常产品标题优化、主图和详情页优化、评价维护、站内外推广、活动策划及提报等运营工作；招聘条件：具有较强的责任心和耐心，对电商领域有浓厚的兴趣和学习意愿；-熟练掌握淘宝、天猫等电商平台运营规则，了解各种推广工具的使用；-有良好的沟通能力和团队协作精神，善于与上级和同事进行有效沟通。熟练OFFICE和PS、PR软件。待遇：基本新资+提成 | H10: 日薪：80-150/天 | I10: =_xlfn.CONCAT(D10,"（学历：",F10," 专业要求：",IF(ISBLANK(M10),"无",M10),"）") -> 电商运营 (电商客服)（学历：大专 专业要求：无） | J10: =LEN(G10) -> 201 | K10: =_xlfn.XLOOKUP(A10,长度要求!A:A,长度要求!E:E) -> 500 | L10: =IF(J10<K10,G10,LEFT(G10,K10)&"……") -> 工作内容：1、负责店铺日常运营，包括商品上架、售后处理、物流跟踪等；日常产品标题优化、主图和详情页优化、评价维护、站内外推广、活动策划及提报等运营工作；招聘条件：具有较强的责任心和耐心，对电商领域有浓厚的兴趣和学习意愿；-熟练掌握淘宝、天猫等电商平台运营规则，了解各种推广工具的使用；-有良好的沟通能力和团队协作精神，善于与上级和同事进行有效沟通。熟练OFFICE和PS、PR软件。待遇：基本新资+提成 | N10: =LEN(M10) -> 0 | O10: =IF(ISBLANK(M10),0,COUNTA(_xlfn.TEXTSPLIT(M10,","))) -> 0
A11: =COUNTIF(B:B,B11) -> 2 | B11: 上海网鱼酒店管理有限公司 | C11: 网鱼创始于1998年，从诞生之初就秉承不断创新的理念，致力于打造多人游戏空间。截至2020年12月31日，网鱼全球会员数超2000万，服务覆盖国内外106个城市。全球拥有超1000家门店，年服务人次超3000万，iG战队倾情代言，是深受全球玩家喜爱的聚玩圣地。2021年推出“网鱼电竞酒店”，正式进军电竞酒店行业，打造跨品类、跨业态、跨平台的综合娱乐型品牌，践行“给用户美好的体验”。 | D11: 门店管培生 | E11: 50 | F11: 大专 | G11: 公司简介：网鱼创始于1998年，起源于上海松江，2015年获得上海市著名商标荣誉称号。作为国内电竞连锁的代表，从诞生之初就秉承不断创新的理念，致力于全球第一电竞社区的打造，为全球电竞玩家提供优质的电竞休闲娱乐服务。截至2021年12月31日，网鱼全球会员数超2000万，服务覆盖国内外82个城市，在美国、英国、加拿大、澳大利亚、新加坡等多个国家开设门店，全球拥有900多家门店，年服务人次超4000万。2021年，网鱼品牌创新升级为“网鱼电竞”，打造游戏玩家的电竞基地；探索多业态，推出“网鱼电竞酒店”，正式进军电竞酒店行业，打造跨品类、跨业态、跨平台的综合娱乐型品牌，践行“给用户美好的体验”。截至2023年12月，网鱼电竞酒店覆盖全国26个主要城市，在营门店数量超过200家。岗位介绍门店管培生（储备店长）：50名工作地点：全国（全国1700家门店，可根据意向城市分配工作城市）。工作职责:1、经营管理：从基层店员历练开始，协助酒店店长进行门店的运营管理，管理门店资产设备、现金、账务，薪资录入，奖金核算；2、学习管理：跟随导师学习门店人员的岗位落实及日常管理；3、品质管理：保证门店卫生品质，逐步掌握处理店铺突发事件；4、参与店铺全岗位知识学习，按照计划参与岗位晋升培训，稳步晋升协助店长管理店面日常及销售管理工作，达成店面销售目标；要求：1、大专学历，2025年或2026年毕业；2、专业不限，连锁经营管理、经管专业等优先，其他专业优秀同学也可；3、仪容仪表端正，良好的沟通表达能力，思路清晰，适应能力强。各阶段岗位薪酬：1、综合月薪：入职后的前4个月4000-5000元左右，第5个月-7个月5000-6000元左右，第8个月晋升店长后，月薪8000元及以上（不同城市薪资略有差异）2、福利：包住宿 | H11: 月薪：5K-10K | I11: =_xlfn.CONCAT(D11,"（学历：",F11," 专业要求：",IF(ISBLANK(M11),"无",M11),"）") -> 门店管培生（学历：大专 专业要求：无） | J11: =LEN(G11) -> 754 | K11: =_xlfn.XLOOKUP(A11,长度要求!A:A,长度要求!E:E) -> 500 | L11: =IF(J11<K11,G11,LEFT(G11,K11)&"……") -> 公司简介：网鱼创始于1998年，起源于上海松江，2015年获得上海市著名商标荣誉称号。作为国内电竞连锁的代表，从诞生之初就秉承不断创新的理念，致力于全球第一电竞社区的打造，为全球电竞玩家提供优质的电竞休闲娱乐服务。截至2021年12月31日，网鱼全球会员数超2000万，服务覆盖国内外82个城市，在美国、英国、加拿大、澳大利亚、新加坡等多个国家开设门店，全球拥有900多家门店，年服务人次超4000万。2021年，网鱼品牌创新升级为“网鱼电竞”，打造游戏玩家的电竞基地；探索多业态，推出“网鱼电竞酒店”，正式进军电竞酒店行业，打造跨品类、跨业态、跨平台的综合娱乐型品牌，践行“给用户美好的体验”。截至2023年12月，网鱼电竞酒店覆盖全国26个主要城市，在营门店数量超过200家。岗位介绍门店管培生（储备店长）：50名工作地点：全国（全国1700家门店，可根据意向城市分配工作城市）。工作职责:1、经营管理：从基层店员历练开始，协助酒店店长进行门店的运营管理，管理门店资产设备、现金、账务，薪资录入，奖金核算；2、学习管理：跟随导师学习门店人员的岗位落实及日常管理；3、品质管理：保证门店卫生品质，逐…… | N11: =LEN(M11) -> 0 | O11: =IF(ISBLANK(M11),0,COUNTA(_xlfn.TEXTSPLIT(M11,","))) -> 0
A12: =COUNTIF(B:B,B12) -> 2 | B12: 上海网鱼酒店管理有限公司 | C12: 网鱼创始于1998年，从诞生之初就秉承不断创新的理念，致力于打造多人游戏空间。截至2020年12月31日，网鱼全球会员数超2000万，服务覆盖国内外106个城市。全球拥有超1000家门店，年服务人次超3000万，iG战队倾情代言，是深受全球玩家喜爱的聚玩圣地。2021年推出“网鱼电竞酒店”，正式进军电竞酒店行业，打造跨品类、跨业态、跨平台的综合娱乐型品牌，践行“给用户美好的体验”。 | D12: 客户经理 | E12: 30 | F12: 大专 | G12: 职责：1、导座服务：①严格执行门店导座SOP标准，提升顾客满意度；②主动观察顾客消费习惯，提供个性化服务；③工作时间需着JK制服，并保持整洁得体的妆容及精神面貌；2、抖音直播：①每日在门店非上客高峰期，使用门店抖音账号，完成2小时直播；②负责直播间的秩序维护和用户互动，积极解答用户问题；③发掘直播间内意向用户，吸引用户到店，提升门店新会员数量；④每日24点前，完成一条抖音视频发布。3、会员运营：①完成企业微信社群搭建、成员邀请及日常维护；②每日回访新客，定期收集top100顾客反馈建议；③每日邀请老顾客到店上网，并为顾客线上订座；4、线上平台维护：①每周按照店长要求，完成高德/百度/腾讯地图/美团平台的优质好评数。②100%邀请团购用户消费后评价。要求：1、性别：女2、年龄：18-24周岁3、学历：大专及以上学历4、形象：身高160CM以上，形象气质佳5、性格特质：活泼开朗，有服务意识，擅沟通喜交流6、经验能力：会端游、有直播或者游戏教练经验者优先薪资待遇1、薪资：月薪5000+；2、福利：每月免费上网时长60小时，免费饮品10杯，简餐半价券42张，其他福利均同门店其他员工；3、销售提成另计，包含但不限于鱼乐卡销售提成 | H12: 月薪：5K-7K | I12: =_xlfn.CONCAT(D12,"（学历：",F12," 专业要求：",IF(ISBLANK(M12),"无",M12),"）") -> 客户经理（学历：大专 专业要求：无） | J12: =LEN(G12) -> 517 | K12: =_xlfn.XLOOKUP(A12,长度要求!A:A,长度要求!E:E) -> 500 | L12: =IF(J12<K12,G12,LEFT(G12,K12)&"……") -> 职责：1、导座服务：①严格执行门店导座SOP标准，提升顾客满意度；②主动观察顾客消费习惯，提供个性化服务；③工作时间需着JK制服，并保持整洁得体的妆容及精神面貌；2、抖音直播：①每日在门店非上客高峰期，使用门店抖音账号，完成2小时直播；②负责直播间的秩序维护和用户互动，积极解答用户问题；③发掘直播间内意向用户，吸引用户到店，提升门店新会员数量；④每日24点前，完成一条抖音视频发布。3、会员运营：①完成企业微信社群搭建、成员邀请及日常维护；②每日回访新客，定期收集top100顾客反馈建议；③每日邀请老顾客到店上网，并为顾客线上订座；4、线上平台维护：①每周按照店长要求，完成高德/百度/腾讯地图/美团平台的优质好评数。②100%邀请团购用户消费后评价。要求：1、性别：女2、年龄：18-24周岁3、学历：大专及以上学历4、形象：身高160CM以上，形象气质佳5、性格特质：活泼开朗，有服务意识，擅沟通喜交流6、经验能力：会端游、有直播或者游戏教练经验者优先薪资待遇1、薪资：月薪5000+；2、福利：每月免费上网时长60小时，免费饮品10杯，简餐半价券42张，其他福利均同门店其他员工；3、销售提…… | N12: =LEN(M12) -> 0 | O12: =IF(ISBLANK(M12),0,COUNTA(_xlfn.TEXTSPLIT(M12,","))) -> 0
A13: =COUNTIF(B:B,B13) -> 4 | B13: 珍岛信息技术（上海）股份有限公司 | C13: 珍岛信息技术（上海）股份有限公司（简称珍岛集团，股票代码02556.HK）是中国最大的营销及销售SaaS公司，也是最早推出T-force营销领域大模型的公司，最早推出AI-Agentforce中台的公司，聚焦数字化与智能化，基于人工智能、大数据技术，是专注数字化智能营销的SaaS服务提供商，于2024年在香港上市。 | D13: 校企合作经理 | E13: 3 | F13: 大专 | G13: 岗位职责：1、负责面向全国本科、高职、中职、技师院校进行数字营销实训软件的销售工作；2、制定区域销售计划并保障计划有效完成，进行系统化成本风控；3、完成区域业务团队组建、培养和绩效管理；4、建立院校业务多元化合作伙伴架构和体系。任职要求：1、不限专业，金融、网络营销、电子商务为佳；2、做事严谨细致，有耐心，有责任心，具有优秀的表达能力与团队协作能力3、具备良好的学习力、承压能力及高度责任心。4、能接受出差 | H13: 月薪：6K-9K | I13: =_xlfn.CONCAT(D13,"（学历：",F13," 专业要求：",IF(ISBLANK(M13),"无",M13),"）") -> 校企合作经理（学历：大专 专业要求：无） | J13: =LEN(G13) -> 204 | K13: =_xlfn.XLOOKUP(A13,长度要求!A:A,长度要求!E:E) -> 500 | L13: =IF(J13<K13,G13,LEFT(G13,K13)&"……") -> 岗位职责：1、负责面向全国本科、高职、中职、技师院校进行数字营销实训软件的销售工作；2、制定区域销售计划并保障计划有效完成，进行系统化成本风控；3、完成区域业务团队组建、培养和绩效管理；4、建立院校业务多元化合作伙伴架构和体系。任职要求：1、不限专业，金融、网络营销、电子商务为佳；2、做事严谨细致，有耐心，有责任心，具有优秀的表达能力与团队协作能力3、具备良好的学习力、承压能力及高度责任心。4、能接受出差 | N13: =LEN(M13) -> 0 | O13: =IF(ISBLANK(M13),0,COUNTA(_xlfn.TEXTSPLIT(M13,","))) -> 0
A14: =COUNTIF(B:B,B14) -> 5 | B14: 宁波革力物流有限公司上海分公司 | C14: 革力物流有限公司总部设在上海,并在深圳,广州,佛山,中山,以及宁波设有分公司,在华北地区也有较好的代理网络。公司网址为：www.gclchina.net公司的代理网络覆盖100多个国家,优势航线为欧洲,地中海,中东印巴,以及澳洲新西兰和东南亚国家除基本海运空运以外，公司还致力于发展进出口代理、清关、仓储、供应链管理等多元化主体化的国际物流服务。主要合作船公司有:MAERSK、APL、EVERGREEN、NORASIA、PIL、HAPAGLIOYD、MSC、COSCO、CSCL、CMA、WANHAI、YANGMING、OOCL；主要合作的航空公司有联邦快递、联合包裹、美国航空、新加坡航空、加拿大航空、新西兰航空、马来西亚航空、以色列航空、法国航空、德国汉莎、奥地利航空、英航、国泰、阿联酋航空等。我们诚邀你的加入，让我们共同致力于打造美好的明天！我们公司全体员工满怀信心，愿以一流的服务、良好的信誉面向世界，竭诚希望与世界各国、全国各地的代理和货主建立良好的合作关系！ | D14: 会计助理（实习生） | E14: 2 | F14: 大专 | G14: 开票基础凭证录入及时完成领导交办的其他事项岗位要求：会计或财务相关专业工作认真、仔细、负责欢迎应届毕业生 | H14: 日薪：120-150/天 | I14: =_xlfn.CONCAT(D14,"（学历：",F14," 专业要求：",IF(ISBLANK(M14),"无",M14),"）") -> 会计助理（实习生）（学历：大专 专业要求：无） | J14: =LEN(G14) -> 52 | K14: =_xlfn.XLOOKUP(A14,长度要求!A:A,长度要求!E:E) -> 500 | L14: =IF(J14<K14,G14,LEFT(G14,K14)&"……") -> 开票基础凭证录入及时完成领导交办的其他事项岗位要求：会计或财务相关专业工作认真、仔细、负责欢迎应届毕业生 | N14: =LEN(M14) -> 0 | O14: =IF(ISBLANK(M14),0,COUNTA(_xlfn.TEXTSPLIT(M14,","))) -> 0
A15: =COUNTIF(B:B,B15) -> 4 | B15: 上海光通信有限公司 | C15: 上海光通信有限公司（英文名ShanghaiGTXSemiconductorCo.,Ltd，下称“GTX”），成立于1988年，于2022年初转型进入集成电路制造领域。 | D15: 良率提升助理技术员 | E15: 5 | F15: 大专 | G15: 岗位描述：1）负责支持在线缺陷监控，处理产线检测的产品、设备，保证产品正常生产，设备正常运行。2）负责监控并处理检测及复检机台的异常运行状况，保证机台正常运行。3）协同工程师进行缺陷改善，建立合格的检测程式和复检程式，发现并通知产生缺陷的制程，减少缺陷的影响范围。4）负责简单的缺陷切片制样，跟进切片结果。任职要求：1）大专及以上学历，专业不限。2）具备良好的沟通能力，具备团队意识。3）倒班工作模式，接受无尘室工作环境。 | H15: 月薪：6K-8K | I15: =_xlfn.CONCAT(D15,"（学历：",F15," 专业要求：",IF(ISBLANK(M15),"无",M15),"）") -> 良率提升助理技术员（学历：大专 专业要求：无） | J15: =LEN(G15) -> 211 | K15: =_xlfn.XLOOKUP(A15,长度要求!A:A,长度要求!E:E) -> 500 | L15: =IF(J15<K15,G15,LEFT(G15,K15)&"……") -> 岗位描述：1）负责支持在线缺陷监控，处理产线检测的产品、设备，保证产品正常生产，设备正常运行。2）负责监控并处理检测及复检机台的异常运行状况，保证机台正常运行。3）协同工程师进行缺陷改善，建立合格的检测程式和复检程式，发现并通知产生缺陷的制程，减少缺陷的影响范围。4）负责简单的缺陷切片制样，跟进切片结果。任职要求：1）大专及以上学历，专业不限。2）具备良好的沟通能力，具备团队意识。3）倒班工作模式，接受无尘室工作环境。 | N15: =LEN(M15) -> 0 | O15: =IF(ISBLANK(M15),0,COUNTA(_xlfn.TEXTSPLIT(M15,","))) -> 0
A16: =COUNTIF(B:B,B16) -> 4 | B16: 上海光通信有限公司 | C16: 上海光通信有限公司（英文名ShanghaiGTXSemiconductorCo.,Ltd，下称“GTX”），成立于1988年，于2022年初转型进入集成电路制造领域。 | D16: 实验室技术员 | E16: 20 | F16: 大专 | G16: 岗位描述：1）按照规程和作业指导书，执行失效分析实验室/可靠性实验室/化学实验室内相关仪器的操作并按照求完成具体失效分析工作。2）按照规程和作业指导书，执行失效分析实验室/可靠性实验室/化学实验室的日常点检，协助处理机台的日常维护工作。任职要求：1）大专以上学历，理工科相关专业。2）接受倒班工作模式，接受无尘室工作环境。3）具备良好的沟通能力和团队合作精神，具备独立工作、分析和解决问题的能力，良好的中英文读写说能力。 | H16: 月薪：6K-8K | I16: =_xlfn.CONCAT(D16,"（学历：",F16," 专业要求：",IF(ISBLANK(M16),"无",M16),"）") -> 实验室技术员（学历：大专 专业要求：无） | J16: =LEN(G16) -> 210 | K16: =_xlfn.XLOOKUP(A16,长度要求!A:A,长度要求!E:E) -> 500 | L16: =IF(J16<K16,G16,LEFT(G16,K16)&"……") -> 岗位描述：1）按照规程和作业指导书，执行失效分析实验室/可靠性实验室/化学实验室内相关仪器的操作并按照求完成具体失效分析工作。2）按照规程和作业指导书，执行失效分析实验室/可靠性实验室/化学实验室的日常点检，协助处理机台的日常维护工作。任职要求：1）大专以上学历，理工科相关专业。2）接受倒班工作模式，接受无尘室工作环境。3）具备良好的沟通能力和团队合作精神，具备独立工作、分析和解决问题的能力，良好的中英文读写说能力。 | N16: =LEN(M16) -> 0 | O16: =IF(ISBLANK(M16),0,COUNTA(_xlfn.TEXTSPLIT(M16,","))) -> 0
A17: =COUNTIF(B:B,B17) -> 7 | B17: 上海地矿物业管理有限公司 | C17: 上海地矿物业管理有限公司隶属于上市市规划和自然资源局。上海地矿物业管理有限公司城市规划展示馆项目。上海城市规划展示馆市国内售价以展示城市规划与发展为主题专业性场馆。 | D17: 展区管理员 | E17: 10 | F17: 大专 | G17: 要求：（1）五官端正、形象气质号，女性165cm，男性175cm以上，年龄30岁以下。（2）语言表达能力强、善于沟通。普通话水平二级乙等以上或具备同等水平。（3）有较强的组织协调能力，团队协作能力，反应敏捷、能妥善处理游客的突发状况，且具备熟练的电脑操作知识。（4）具有一定的英语口语能力，能与外宾简单交流。薪资待遇：5000-6000元/月其他福利：早中餐、高温费、年终奖、大礼包等实习生3000元+500元全勤奖，国企，提供完善的培训，实习表现优秀者毕业后优先录用。录用后缴纳四金，提供年终奖、高温费、大礼包，详情面谈。 | H17: 月薪：5K-6K | I17: =_xlfn.CONCAT(D17,"（学历：",F17," 专业要求：",IF(ISBLANK(M17),"无",M17),"）") -> 展区管理员（学历：大专 专业要求：无） | J17: =LEN(G17) -> 262 | K17: =_xlfn.XLOOKUP(A17,长度要求!A:A,长度要求!E:E) -> 500 | L17: =IF(J17<K17,G17,LEFT(G17,K17)&"……") -> 要求：（1）五官端正、形象气质号，女性165cm，男性175cm以上，年龄30岁以下。（2）语言表达能力强、善于沟通。普通话水平二级乙等以上或具备同等水平。（3）有较强的组织协调能力，团队协作能力，反应敏捷、能妥善处理游客的突发状况，且具备熟练的电脑操作知识。（4）具有一定的英语口语能力，能与外宾简单交流。薪资待遇：5000-6000元/月其他福利：早中餐、高温费、年终奖、大礼包等实习生3000元+500元全勤奖，国企，提供完善的培训，实习表现优秀者毕业后优先录用。录用后缴纳四金，提供年终奖、高温费、大礼包，详情面谈。 | N17: =LEN(M17) -> 0 | O17: =IF(ISBLANK(M17),0,COUNTA(_xlfn.TEXTSPLIT(M17,","))) -> 0
A18: =COUNTIF(B:B,B18) -> 6 | B18: 上海点晴信息科技有限公司 | C18: 上海点晴信息科技有限公司(ALCHEMYInformationtech-nologyCo.,Ltd)成立于2013年，是一家集独立游戏开发、高品质游戏美术制作服务及游戏美术赛事运营为一体的移动互联网公司。获高新技术企业，专精特新企业、科技小巨人企业、徐汇区企业技术中心、上海市设计创新中心等荣誉。作为腾讯，网易，育碧，米哈游，拳头，电魂，英雄互娱等知名研发公司的核心供应商，点晴参与制作了刺客信条、王者荣耀、原神、绝地求生、阴阳师、第五人格、狐妖小红娘、蛋仔派对等国内外各类型最前沿的主流游戏，致力于为全球市场提供自主研发的高品质游戏娱乐产品。公司旗下教育品牌【第九联盟】专注于CG行业人才储备及校企产学研项目;【GGAC数字艺术平台】集CG领域作品发布及赛事运营于一体。 | D18: 3D模型师/3D建模师 | E18: 20 | F18: 大专 | G18: 负责制作游戏内相关道具场景的建模，熟练使用3Dmax，ps，maya，zb等软件，熟悉次世代制作流程者优先。 | H18: 月薪：5K-8K | I18: =_xlfn.CONCAT(D18,"（学历：",F18," 专业要求：",IF(ISBLANK(M18),"无",M18),"）") -> 3D模型师/3D建模师（学历：大专 专业要求：无） | J18: =LEN(G18) -> 54 | K18: =_xlfn.XLOOKUP(A18,长度要求!A:A,长度要求!E:E) -> 500 | L18: =IF(J18<K18,G18,LEFT(G18,K18)&"……") -> 负责制作游戏内相关道具场景的建模，熟练使用3Dmax，ps，maya，zb等软件，熟悉次世代制作流程者优先。 | N18: =LEN(M18) -> 0 | O18: =IF(ISBLANK(M18),0,COUNTA(_xlfn.TEXTSPLIT(M18,","))) -> 0
A19: =COUNTIF(B:B,B19) -> 5 | B19: 上海汇珏科技集团股份有限公司 | C19: 汇珏集团成立于2002年，是一家集能源系统集成解决方案与智能网络通信设备服务型制造的高新技术企业，公司致力于成为通信及能源行业的领跑者。总部位于上海自贸区临港新片区，注册资金10778万元，目前在全国拥有6家全资子公司。在上海奉贤、江苏海安建立了3大生产基地，总占地面积超20万余平方米，拥有员工超数千人，销售和服务网点遍布全国各个城市，产品远销欧洲、北美、东南亚等多个国家和地区。汇珏网络先后获得了“高新技术企业”、“服务型制造示范”、“国家知识产权优势企业”、“上海专利示范企业”、“上海市企业技术中心”、“上海市著名商标”、“上海名牌产品”等众多荣誉。经过20多年的发展创新，产品及服务覆盖智慧ICT网络解决方案、数据中心解决方案、智慧能源解决方案、智慧移动通信解决方案、智慧建筑一体化解决方案、智慧城市一站式服务六大方向，产品广泛应用于通信、电力、新能源、交通、建筑、医疗等多个行业，实现了产品的多元化创新和商务模式向服务型制造升级。企业竞争力和市场地位不断提升，其中最新研发的智慧能源解决方案已应用市政、交通、教育、运营商等国内外多个行业，同时在国际市场中崭露锋芒。公司发展历程：2002-2004公司成立，引进先进技术；2005-2006办公厂房落成，公司商标注册；2007-2010开发“光进铜退室外机柜”，中标中国电信；2011-2012“PLC分路器”开发成功，中标三大运营商，新建生产基地；2013-2014投建江苏100亩光器件产业园，成立汇珏智能软件公司，开发网优软件产品，填补国内空白，签约中国电信；2015-2016集团信息化平台应用提升专业化管理。产品智能化升级，研发IODN等产品，推动智能化制造，连续中标国内三大运营商。公司秉承“汇当凌珏顶，一览众山小”的企业精神，先后获得上海市“高新技术企业”，“上海市著名商标”，“科技小巨人企业（培育）”，“专精特新企业”，“创新型企业”，等荣誉，多个产品获得了“上海市高新技术成果转化项目”。 | D19: 外贸业务助理 | E19: 5 | F19: 大专 | G19: 1.英语大学四级及以上，书面英语读写无障碍，口语交流流利。2.优秀的沟通表达能力与亲和力，有出色的组织协调能力与执行力。3.工作积极主动、认真负责，责任心强。4.善于组织策划活动，有服务意识。5.持有有效驾照，驾驶技术熟练者优先。(因工作经常会涉及到海外客户接待需求)。 | H19: 日薪：120-150/天 | I19: =_xlfn.CONCAT(D19,"（学历：",F19," 专业要求：",IF(ISBLANK(M19),"无",M19),"）") -> 外贸业务助理（学历：大专 专业要求：国际经济与贸易,国际贸易学,贸易经济） | J19: =LEN(G19) -> 135 | K19: =_xlfn.XLOOKUP(A19,长度要求!A:A,长度要求!E:E) -> 500 | L19: =IF(J19<K19,G19,LEFT(G19,K19)&"……") -> 1.英语大学四级及以上，书面英语读写无障碍，口语交流流利。2.优秀的沟通表达能力与亲和力，有出色的组织协调能力与执行力。3.工作积极主动、认真负责，责任心强。4.善于组织策划活动，有服务意识。5.持有有效驾照，驾驶技术熟练者优先。(因工作经常会涉及到海外客户接待需求)。 | M19: 国际经济与贸易,国际贸易学,贸易经济 | N19: =LEN(M19) -> 18 | O19: =IF(ISBLANK(M19),0,COUNTA(_xlfn.TEXTSPLIT(M19,","))) -> 3
A20: =COUNTIF(B:B,B20) -> 1 | B20: 上海世博中心有限公司 | C20: 上海世博中心，作为上海市机关事务管理局下属国有企业，同样具备了举办展览、会议、活动以及房屋租赁的功能，与上展中心在浦江两岸形成东西呼应的两座上海标志性建筑。上海世博中心以成为世界级的会议中心为目标。世博会期间，其承担了庆典、交流、贵宾接待、新闻发布和指挥运营等重要任务。世博会后，已转型成为大型高规格国际会议的重要场所，一方面承担政务服务功能，成为上海市“两会”及其他政务性会议的重要举办场所；另一方面还要承载社会功能，对市场和社会开放，以其会议、展览、活动（宴会）等专业功能形成核心竞争力，充分展示上海国际大都会形象，提升上海城市的综合竞争力。 | D20: 会展接待服务 | E20: 4 | F20: 初中及以下 | G20: 1.女：身高1.65米以上，专业不限；2.品貌端正、无纹身、对工作有责任心，能吃苦耐劳；3.按照客户要求布置好会场，做好会前的准备工作；4.做好会中接待工作，确保会议有序进行；5.本岗位可招收实习生；6.完成上级安排的其他工作。 | H20: 月薪：5K-9K | I20: =_xlfn.CONCAT(D20,"（学历：",F20," 专业要求：",IF(ISBLANK(M20),"无",M20),"）") -> 会展接待服务（学历：初中及以下 专业要求：无） | J20: =LEN(G20) -> 114 | K20: =_xlfn.XLOOKUP(A20,长度要求!A:A,长度要求!E:E) -> 500 | L20: =IF(J20<K20,G20,LEFT(G20,K20)&"……") -> 1.女：身高1.65米以上，专业不限；2.品貌端正、无纹身、对工作有责任心，能吃苦耐劳；3.按照客户要求布置好会场，做好会前的准备工作；4.做好会中接待工作，确保会议有序进行；5.本岗位可招收实习生；6.完成上级安排的其他工作。 | N20: =LEN(M20) -> 0 | O20: =IF(ISBLANK(M20),0,COUNTA(_xlfn.TEXTSPLIT(M20,","))) -> 0
A21: =COUNTIF(B:B,B21) -> 2 | B21: 上海万厦建筑装饰加固工程有限公司 | C21: 上海万厦建筑装饰加固工程有限公司是一家装饰加固的专业公司，影院建设的集成单位。公司专业配套、工种齐全。具有工艺设计、建声设计、装修设计、结构设计、机电设计以及工程管理与各施工项目经理部。在长期的工程实践中已取得了丰富的经验，形成了设计施工一体化的操作模式，取得了丰硕的业绩。公司自上世纪九十年代至今已先后设计和施工了影剧院、演剧场、文化馆等几百项文化设施项目及公共商业设施项目，取得了良好的社会信誉和业主好评。 | D21: 软件开发设计师 | E21: 2 | F21: 大专 | G21: 技术基础：掌握前端基础技术，包括HTML/CSS/JavaScript，了解ES6及以上语法；熟悉或初步了解小程序开发技术栈（WXML/WXSS），有使用微信开发者工具的基础经验；了解Vue、React等前端框架，或Python、Java等任一后端语言者优先。3.工具与能力：能使用微信开发者工具完成简单代码编写、调试与预览；具备基础的逻辑思维和问题排查能力，能理解简单业务需求并配合完成代码辅助工作；会使用Git等版本控制工具（如GitHub、GitLab）者加分。 | H21: 日薪：150-200/天 | I21: =_xlfn.CONCAT(D21,"（学历：",F21," 专业要求：",IF(ISBLANK(M21),"无",M21),"）") -> 软件开发设计师（学历：大专 专业要求：无） | J21: =LEN(G21) -> 234 | K21: =_xlfn.XLOOKUP(A21,长度要求!A:A,长度要求!E:E) -> 500 | L21: =IF(J21<K21,G21,LEFT(G21,K21)&"……") -> 技术基础：掌握前端基础技术，包括HTML/CSS/JavaScript，了解ES6及以上语法；熟悉或初步了解小程序开发技术栈（WXML/WXSS），有使用微信开发者工具的基础经验；了解Vue、React等前端框架，或Python、Java等任一后端语言者优先。3.工具与能力：能使用微信开发者工具完成简单代码编写、调试与预览；具备基础的逻辑思维和问题排查能力，能理解简单业务需求并配合完成代码辅助工作；会使用Git等版本控制工具（如GitHub、GitLab）者加分。 | N21: =LEN(M21) -> 0 | O21: =IF(ISBLANK(M21),0,COUNTA(_xlfn.TEXTSPLIT(M21,","))) -> 0
A22: =COUNTIF(B:B,B22) -> 2 | B22: 上海万厦建筑装饰加固工程有限公司 | C22: 上海万厦建筑装饰加固工程有限公司是一家装饰加固的专业公司，影院建设的集成单位。公司专业配套、工种齐全。具有工艺设计、建声设计、装修设计、结构设计、机电设计以及工程管理与各施工项目经理部。在长期的工程实践中已取得了丰富的经验，形成了设计施工一体化的操作模式，取得了丰硕的业绩。公司自上世纪九十年代至今已先后设计和施工了影剧院、演剧场、文化馆等几百项文化设施项目及公共商业设施项目，取得了良好的社会信誉和业主好评。 | D22: 装饰设计 | E22: 5 | F22: 大专 | G22: 软件技能：熟练使用CAD（绘制平面图、施工图）、SketchUp（基础建模），掌握3DMax/Blender（建模）、Photoshop（效果图后期）者优先。具备基础的空间布局、色彩搭配审美；了解常见装饰材料（如板材、涂料）、施工工艺基础知识者。 | H22: 日薪：150-200/天 | I22: =_xlfn.CONCAT(D22,"（学历：",F22," 专业要求：",IF(ISBLANK(M22),"无",M22),"）") -> 装饰设计（学历：大专 专业要求：无） | J22: =LEN(G22) -> 123 | K22: =_xlfn.XLOOKUP(A22,长度要求!A:A,长度要求!E:E) -> 500 | L22: =IF(J22<K22,G22,LEFT(G22,K22)&"……") -> 软件技能：熟练使用CAD（绘制平面图、施工图）、SketchUp（基础建模），掌握3DMax/Blender（建模）、Photoshop（效果图后期）者优先。具备基础的空间布局、色彩搭配审美；了解常见装饰材料（如板材、涂料）、施工工艺基础知识者。 | N22: =LEN(M22) -> 0 | O22: =IF(ISBLANK(M22),0,COUNTA(_xlfn.TEXTSPLIT(M22,","))) -> 0
A23: =COUNTIF(B:B,B23) -> 3 | B23: 上海云众名远信息技术有限公司 | C23: 上海云众专注于移动互联网整合营销，汇集了全国数家移动媒体，是360在上海地区的优秀代理商。为客户提供全渠道“一对一”顾问式的定制服务方案，利用深度数据分析挖掘工具、可视化报表处理功能、高精度的实时用户画像，先进的搜索引擎技术实施精准投放广告，从广告主企业实际需求的出发，实现企业网络营销效果，提高广告转化效果。基于360AI大模型，提供元宇宙定制、AI数字人智能化业务定制服务，致力于通过前沿科技为企业提供数字化营销管理专属解决方案，助力企业获客提效。 | D23: 广告运营专员 | E23: 3 | F23: 大专 | G23: 岗位职责：1、与客户沟通，及时了解客户需求和广告投放计划；2、根据客户产品制定投放策略，指导客户有效执行；3、对广告投放进行效果监控，及时反馈，并定期制定数据分析报告；4、跟进续费事宜，维护客户关系，确保客户长期合作；5、定期拜访客户，了解需求和效果，以便做账户优化和调整。任职要求：1、专业不限，积极主动，执行力强，踏实稳定，有强烈责任心和沟通能力；2、能熟练运用excel、PPT等办公软件；3、实习生可免费提供住宿，可转正。 | H23: 月薪：4K-6K | I23: =_xlfn.CONCAT(D23,"（学历：",F23," 专业要求：",IF(ISBLANK(M23),"无",M23),"）") -> 广告运营专员（学历：大专 专业要求：无） | J23: =LEN(G23) -> 215 | K23: =_xlfn.XLOOKUP(A23,长度要求!A:A,长度要求!E:E) -> 500 | L23: =IF(J23<K23,G23,LEFT(G23,K23)&"……") -> 岗位职责：1、与客户沟通，及时了解客户需求和广告投放计划；2、根据客户产品制定投放策略，指导客户有效执行；3、对广告投放进行效果监控，及时反馈，并定期制定数据分析报告；4、跟进续费事宜，维护客户关系，确保客户长期合作；5、定期拜访客户，了解需求和效果，以便做账户优化和调整。任职要求：1、专业不限，积极主动，执行力强，踏实稳定，有强烈责任心和沟通能力；2、能熟练运用excel、PPT等办公软件；3、实习生可免费提供住宿，可转正。 | N23: =LEN(M23) -> 0 | O23: =IF(ISBLANK(M23),0,COUNTA(_xlfn.TEXTSPLIT(M23,","))) -> 0
A24: =COUNTIF(B:B,B24) -> 3 | B24: 上海三客友文化传播有限公司 | C24: 公司成立于2021年04月01日，其创始人以及各合伙人均在本行业耕耘十余年，具有相当的专业能力以及行业分析力。现主营业务为全国各大行业展会行业头部展商展台的现场运营和各大知名品牌的线下推广活动以及国企央企等上市企业宣传片拍摄、短视频制作及新媒体运营等。服务企业有中国铁路局上海工务段、中粮集团、龙湖地产、奔驰、北汽、吉利、极狐、松下、尼康、三菱电机、丰收日集团、花嫁丽舍、沙田物业、上海婚庆行业协会等等。现由于公司业务扩张，望有意向的同行业有志青年及对广告会展行业有兴趣的小伙伴加入团队。 | D24: 会展项目执行及管理 | E24: 2 | F24: 大专 | G24: 1.项目策划与执行：参与展会项目的策划，包括但不限于确定展会主题、制定展会流程、安排展会时间表等，确保项目从策划到执行的顺利进行。2.沟通协调：与各部门、参展商、供应商等建立有效的沟通机制，确保信息的准确传达和项目的顺利推进。3.现场管理：在展会期间，负责现场的协调与管理工作，确保展会现场的秩序和安全。4.数据分析与报告：收集展会相关数据，进行分析并撰写报告，为公司的决策提供有力支持。岗位要求：展会现场执行、并辅助项目经理做好向下内部管理工作，例如：各类人员招募、礼品物料整理、了解基础搭建及制作知识，简单制作统计表等；具有一定的社交能力。 | H24: 月薪：5K-8K | I24: =_xlfn.CONCAT(D24,"（学历：",F24," 专业要求：",IF(ISBLANK(M24),"无",M24),"）") -> 会展项目执行及管理（学历：大专 专业要求：无） | J24: =LEN(G24) -> 272 | K24: =_xlfn.XLOOKUP(A24,长度要求!A:A,长度要求!E:E) -> 500 | L24: =IF(J24<K24,G24,LEFT(G24,K24)&"……") -> 1.项目策划与执行：参与展会项目的策划，包括但不限于确定展会主题、制定展会流程、安排展会时间表等，确保项目从策划到执行的顺利进行。2.沟通协调：与各部门、参展商、供应商等建立有效的沟通机制，确保信息的准确传达和项目的顺利推进。3.现场管理：在展会期间，负责现场的协调与管理工作，确保展会现场的秩序和安全。4.数据分析与报告：收集展会相关数据，进行分析并撰写报告，为公司的决策提供有力支持。岗位要求：展会现场执行、并辅助项目经理做好向下内部管理工作，例如：各类人员招募、礼品物料整理、了解基础搭建及制作知识，简单制作统计表等；具有一定的社交能力。 | N24: =LEN(M24) -> 0 | O24: =IF(ISBLANK(M24),0,COUNTA(_xlfn.TEXTSPLIT(M24,","))) -> 0
A25: =COUNTIF(B:B,B25) -> 3 | B25: 上海明华智慧城市运营管理有限公司 | C25: 上海明华智慧城市运营管理有限公司（简称明华）成立于1992年8月，为上海市最早获得国家物业管理一级资质企业之一。近三十年来，明华始终秉承“快乐服务，追求卓越”的服务理念，不走寻常路，差异发展、创新经营，先人一步走出了一条“公众物业管理”的探索之路；在个性化、人性化、国际化理念的指引下，通过量身定制的服务研发和产品输出，成为物业行业中公众物业管理领域的领先者。在公众物业管理领域，明华在上海乃至国内外具有影响力的主要项目如下：公众展览场馆——中华艺术宫、上海科技馆、上海自然博物馆、上海历史博物馆等公众演艺场馆——上海交响乐团、上海京剧院乐团、上海京剧院传习馆等公众体育场馆——上海网球中心公众交通枢纽——磁浮列车龙阳路站公众绿地公园——上海辰山植物园、上海动物园金融园区——中国人寿保险数据中心大学校园——上海交通大学、华东理工大学闵行校区高端写字楼——航汇大厦 | D25: 展馆管理 | E25: 10 | F25: 大专 | G25: 岗位职责1.学习了解场馆内容主题，整理讲解词，向游客进行解说工作；2.负责场馆内指引接待工作，维护参观秩序；3.协助做好团队的其他工作。任职资格1.有亲和力，形象气质佳；2.有较强的语言表达能力，普通话标准；3.熟练掌握办公软件操作能力。 | H25: 月薪：4K-5K | I25: =_xlfn.CONCAT(D25,"（学历：",F25," 专业要求：",IF(ISBLANK(M25),"无",M25),"）") -> 展馆管理（学历：大专 专业要求：无） | J25: =LEN(G25) -> 119 | K25: =_xlfn.XLOOKUP(A25,长度要求!A:A,长度要求!E:E) -> 500 | L25: =IF(J25<K25,G25,LEFT(G25,K25)&"……") -> 岗位职责1.学习了解场馆内容主题，整理讲解词，向游客进行解说工作；2.负责场馆内指引接待工作，维护参观秩序；3.协助做好团队的其他工作。任职资格1.有亲和力，形象气质佳；2.有较强的语言表达能力，普通话标准；3.熟练掌握办公软件操作能力。 | N25: =LEN(M25) -> 0 | O25: =IF(ISBLANK(M25),0,COUNTA(_xlfn.TEXTSPLIT(M25,","))) -> 0
A26: =COUNTIF(B:B,B26) -> 2 | B26: 予童家庭服务（上海）有限公司 | C26: 予童家庭服务（BabyNanny），以“重塑美好育儿生态”为使命，专注为高净值家庭提供育婴照护、婴儿早教、孩童陪伴等服务。作为高标准母婴护理及高质量家庭服务的坚定笃行者，予童为同样追求育儿品质的家庭，定制集育婴护理、入户指导和社群体验“三维一体”的婴童成长呵护方案，让育儿回归优雅和从容。以“百里挑一”的严苛标准遴选育婴师，打造迎合高端家庭需求的培塑实训，冀期予童的每一名育婴师，都能成为宝宝的温情暖手、宝妈的得力助手、家庭的坚实帮手。 | D26: 家庭育婴师 | E26: 10 | F26: 大专 | G26: 一、工作地点上海全市二、岗位职责-全面负责新生儿的生活照料，涵盖喂养、洗澡、抚触、更换尿布等环节，保障宝宝的清洁与舒适。-密切留意宝宝的生长发育状况，诸如身高、体重、睡眠、大小便等方面，一旦察觉异常立即向家长或医生反馈。-依据宝宝的年龄及发展阶段，精心制定科学合理的喂养计划与作息时间表，悉心培养宝宝良好的生活习惯。-开展早期教育与启蒙工作，借助游戏、互动等多种方式，推动宝宝的认知、语言、运动以及社交能力的发展。-承担宝宝衣物、用品的清洗与消毒工作，确保宝宝生活环境的整洁与卫生。-与家长保持高效且良好的沟通，深入了解家长的需求与关注重点，给予专业的育婴建议和指导。-协助家长妥善处理宝宝的其他相关事务，像就医、接种疫苗等。三、任职要求需要会做饭。持有专业的育婴师资格证书，例如育婴员职业资格证书等优先。具有早教中心、托育园、幼儿园实习经验者优先。对婴幼儿事业充满热爱，拥有爱心、耐心和责任心，具备良好的职业道德和素养。具备出色的沟通能力和团队协作精神，能够与家长及其他工作人员构建起良好的关系。身体健康，拥有良好的心理素质和抗压能力。具有一定的学习和创新能力，能够持续更新育婴知识和技能。 | H26: 日薪：80-150/天 | I26: =_xlfn.CONCAT(D26,"（学历：",F26," 专业要求：",IF(ISBLANK(M26),"无",M26),"）") -> 家庭育婴师（学历：大专 专业要求：护理,学前教育,助产） | J26: =LEN(G26) -> 496 | K26: =_xlfn.XLOOKUP(A26,长度要求!A:A,长度要求!E:E) -> 500 | L26: =IF(J26<K26,G26,LEFT(G26,K26)&"……") -> 一、工作地点上海全市二、岗位职责-全面负责新生儿的生活照料，涵盖喂养、洗澡、抚触、更换尿布等环节，保障宝宝的清洁与舒适。-密切留意宝宝的生长发育状况，诸如身高、体重、睡眠、大小便等方面，一旦察觉异常立即向家长或医生反馈。-依据宝宝的年龄及发展阶段，精心制定科学合理的喂养计划与作息时间表，悉心培养宝宝良好的生活习惯。-开展早期教育与启蒙工作，借助游戏、互动等多种方式，推动宝宝的认知、语言、运动以及社交能力的发展。-承担宝宝衣物、用品的清洗与消毒工作，确保宝宝生活环境的整洁与卫生。-与家长保持高效且良好的沟通，深入了解家长的需求与关注重点，给予专业的育婴建议和指导。-协助家长妥善处理宝宝的其他相关事务，像就医、接种疫苗等。三、任职要求需要会做饭。持有专业的育婴师资格证书，例如育婴员职业资格证书等优先。具有早教中心、托育园、幼儿园实习经验者优先。对婴幼儿事业充满热爱，拥有爱心、耐心和责任心，具备良好的职业道德和素养。具备出色的沟通能力和团队协作精神，能够与家长及其他工作人员构建起良好的关系。身体健康，拥有良好的心理素质和抗压能力。具有一定的学习和创新能力，能够持续更新育婴知识和技能。 | M26: 护理,学前教育,助产 | N26: =LEN(M26) -> 10 | O26: =IF(ISBLANK(M26),0,COUNTA(_xlfn.TEXTSPLIT(M26,","))) -> 3
A27: =COUNTIF(B:B,B27) -> 3 | B27: 上海明华智慧城市运营管理有限公司 | C27: 上海明华智慧城市运营管理有限公司（简称明华）成立于1992年8月，为上海市最早获得国家物业管理一级资质企业之一。近三十年来，明华始终秉承“快乐服务，追求卓越”的服务理念，不走寻常路，差异发展、创新经营，先人一步走出了一条“公众物业管理”的探索之路；在个性化、人性化、国际化理念的指引下，通过量身定制的服务研发和产品输出，成为物业行业中公众物业管理领域的领先者。在公众物业管理领域，明华在上海乃至国内外具有影响力的主要项目如下：公众展览场馆——中华艺术宫、上海科技馆、上海自然博物馆、上海历史博物馆等公众演艺场馆——上海交响乐团、上海京剧院乐团、上海京剧院传习馆等公众体育场馆——上海网球中心公众交通枢纽——磁浮列车龙阳路站公众绿地公园——上海辰山植物园、上海动物园金融园区——中国人寿保险数据中心大学校园——上海交通大学、华东理工大学闵行校区高端写字楼——航汇大厦 | D27: 行政助理 | E27: 2 | F27: 大专 | G27: 岗位职责在带教人指导下，协助完成日常行政事务、文档处理、信息整理及基础沟通协调工作，同时熟悉办公流程与职场规范，提升基础办公技能。1.文档处理与资料管理-协助进行文档的录入、排版、打印、复印与装订，确保文档格式规范、内容准确。-参与资料的整理与归档，2.日常行政事务协助-负责办公区域的基础后勤支持，如整理办公环境、补充办公用品（笔、纸、打印机耗材等）、登记领用情况。-协助接待来访人员，做好引导、登记，通知相关同事对接；3.信息整理与数据统计-协助收集、整理各类基础信息，按照要求进行简单的分类与汇总。-及时更新基础信息台账，保证信息的时效性。4.沟通协调与事务跟进-协助在部门内部或跨部门间传递文件、传达简单通知，确保信息传递及时。-跟进简单事务的进展（如待办事项、任务反馈等），并向带教人或上级汇报进度。任职资格1.仔细认真，沟通协调能力较强；2.办公软件熟练；3.有意向在物业行业长期发展者优先。 | H27: 月薪：5K-6K | I27: =_xlfn.CONCAT(D27,"（学历：",F27," 专业要求：",IF(ISBLANK(M27),"无",M27),"）") -> 行政助理（学历：大专 专业要求：无） | J27: =LEN(G27) -> 402 | K27: =_xlfn.XLOOKUP(A27,长度要求!A:A,长度要求!E:E) -> 500 | L27: =IF(J27<K27,G27,LEFT(G27,K27)&"……") -> 岗位职责在带教人指导下，协助完成日常行政事务、文档处理、信息整理及基础沟通协调工作，同时熟悉办公流程与职场规范，提升基础办公技能。1.文档处理与资料管理-协助进行文档的录入、排版、打印、复印与装订，确保文档格式规范、内容准确。-参与资料的整理与归档，2.日常行政事务协助-负责办公区域的基础后勤支持，如整理办公环境、补充办公用品（笔、纸、打印机耗材等）、登记领用情况。-协助接待来访人员，做好引导、登记，通知相关同事对接；3.信息整理与数据统计-协助收集、整理各类基础信息，按照要求进行简单的分类与汇总。-及时更新基础信息台账，保证信息的时效性。4.沟通协调与事务跟进-协助在部门内部或跨部门间传递文件、传达简单通知，确保信息传递及时。-跟进简单事务的进展（如待办事项、任务反馈等），并向带教人或上级汇报进度。任职资格1.仔细认真，沟通协调能力较强；2.办公软件熟练；3.有意向在物业行业长期发展者优先。 | N27: =LEN(M27) -> 0 | O27: =IF(ISBLANK(M27),0,COUNTA(_xlfn.TEXTSPLIT(M27,","))) -> 0
A28: =COUNTIF(B:B,B28) -> 2 | B28: 中国电信股份有限公司上海莘闵电信局 | C28: 中国电信股份有限公司上海莘闵电信局坐落于闵行区莘东路199号，简称莘闵电信局。前身为上海市电话局莘闵区局。2000年7月1日，中国电信集团上海市电信公司成立后，更名为上海市电信公司莘闵电信局；2008年3月，更名为中国电信股份有限公司上海莘闵电信局。中国电信股份有限公司上海莘闵电信局提供固定电话、移动通信、宽带互联网接入、互联网电视、卫星通信、信息化应用等泛在网络和综合智能信息服务能力，服务闵行区内各类客户，始终保持区域内通信市场的领先地位。莘闵电信局以党的建设统领企业发展全局，以改革创新为动力，加快推进"网络智能化、业务生态化和运营智慧化"，积极构建"五大业务"生态圈，努力做领先的综合智能信息服务运营商,为闵行区经济发展和网络强国建设做出更大贡献，助推闵行区信息化及经济高速增长。 | D28: 门店经理见习生 | E28: 30 | F28: 大专 | G28: 电信门店的整体运营与业绩达成，核心涵盖经营指标、团队管理、客户服务、营销与渠道协同、合规与风险控制等关键模块。 | H28: 日薪：80-150/天 | I28: =_xlfn.CONCAT(D28,"（学历：",F28," 专业要求：",IF(ISBLANK(M28),"无",M28),"）") -> 门店经理见习生（学历：大专 专业要求：无） | J28: =LEN(G28) -> 55 | K28: =_xlfn.XLOOKUP(A28,长度要求!A:A,长度要求!E:E) -> 500 | L28: =IF(J28<K28,G28,LEFT(G28,K28)&"……") -> 电信门店的整体运营与业绩达成，核心涵盖经营指标、团队管理、客户服务、营销与渠道协同、合规与风险控制等关键模块。 | N28: =LEN(M28) -> 0 | O28: =IF(ISBLANK(M28),0,COUNTA(_xlfn.TEXTSPLIT(M28,","))) -> 0
A29: =COUNTIF(B:B,B29) -> 4 | B29: 上海樱帆望文化传媒有限公司 | C29: 樱帆电竞成立于2015年8月，以电竞赛事组织策划执行和直转播节目制作为业务核心。赛事组织板块已经完成过2018年雅加达亚运会、2018-2019年WESG全球总决赛、2019-2024OPL职业联赛等各类国内外高级别比赛的赛事组织工作，时至今日樱帆电竞已经完成超过500个游戏项目赛事组织执行工作。2021年公司成立直转播节目制作业务板块，完成了征途全民争霸赛总决赛暨年终盛典、三届永劫无间高校总决赛、剑网3竞技群英赛、DCDC冠军联赛、实况足球世总赛、影之诗联赛、漫威争锋冠军杯、SCS年度总决赛、蛋仔派对高校总决赛、剑网3竞技大师赛等在内的上百个大型项目的直转播节目制作工作。目前在上海拥有包括1个制播中心及5套演播棚在内的1500平专业节目制播场地以及一个技术中心、一个创意中心，专业服务于各类电竞赛事及泛娱乐节目制作。 | D29: 电竞赛事直转播播控岗位实习生 | E29: 2 | F29: 大专 | G29: 一、职位概述参与电竞赛事直转播工作，协助专业团队确保赛事直播的顺利进行。二、主要职责1.直播协助●深度参与电竞赛事直转播过程中的播控操作工作，包括但不限于设备的开启与关闭、信号切换、画面调整等。●密切监控直播信号，及时发现并反馈直播中的异常情况，确保直播质量。2.学习提升●学习电竞赛事直转播的流程和技术，熟悉各类播控设备的使用。●参加内部培训，提升专业技能和对电竞行业的认知。3.资料整理●整理电竞赛事直转播相关的技术资料和数据记录。●协助撰写简单的直播报告。4.播控任务●完成上级交办的其他与电竞赛事直转播播控相关的工作。内容包含但不限于导播切台、VCR、字幕机等。三、任职要求1.专业背景●传媒、广播电视、数字媒体技术、电子竞技等相关专业优先。2.技能要求●具备一定的计算机操作能力，熟悉常用办公软件。●对电竞有浓厚兴趣，了解电竞赛事直播特点，需要有一定的相关经验(社团、兼职等均可)。3.态度品质●工作认真负责，细心耐心，有较强的学习能力和团队合作精神。4.学历要求●大专以上学历，26届27届毕业生优先。 | H29: 日薪：150-200/天 | I29: =_xlfn.CONCAT(D29,"（学历：",F29," 专业要求：",IF(ISBLANK(M29),"无",M29),"）") -> 电竞赛事直转播播控岗位实习生（学历：大专 专业要求：广播电视学,广播电视,广播影视节目制作,广播电视编导） | J29: =LEN(G29) -> 457 | K29: =_xlfn.XLOOKUP(A29,长度要求!A:A,长度要求!E:E) -> 500 | L29: =IF(J29<K29,G29,LEFT(G29,K29)&"……") -> 一、职位概述参与电竞赛事直转播工作，协助专业团队确保赛事直播的顺利进行。二、主要职责1.直播协助●深度参与电竞赛事直转播过程中的播控操作工作，包括但不限于设备的开启与关闭、信号切换、画面调整等。●密切监控直播信号，及时发现并反馈直播中的异常情况，确保直播质量。2.学习提升●学习电竞赛事直转播的流程和技术，熟悉各类播控设备的使用。●参加内部培训，提升专业技能和对电竞行业的认知。3.资料整理●整理电竞赛事直转播相关的技术资料和数据记录。●协助撰写简单的直播报告。4.播控任务●完成上级交办的其他与电竞赛事直转播播控相关的工作。内容包含但不限于导播切台、VCR、字幕机等。三、任职要求1.专业背景●传媒、广播电视、数字媒体技术、电子竞技等相关专业优先。2.技能要求●具备一定的计算机操作能力，熟悉常用办公软件。●对电竞有浓厚兴趣，了解电竞赛事直播特点，需要有一定的相关经验(社团、兼职等均可)。3.态度品质●工作认真负责，细心耐心，有较强的学习能力和团队合作精神。4.学历要求●大专以上学历，26届27届毕业生优先。 | M29: 广播电视学,广播电视,广播影视节目制作,广播电视编导 | N29: =LEN(M29) -> 26 | O29: =IF(ISBLANK(M29),0,COUNTA(_xlfn.TEXTSPLIT(M29,","))) -> 4
A30: =COUNTIF(B:B,B30) -> 4 | B30: 上海樱帆望文化传媒有限公司 | C30: 樱帆电竞成立于2015年8月，以电竞赛事组织策划执行和直转播节目制作为业务核心。赛事组织板块已经完成过2018年雅加达亚运会、2018-2019年WESG全球总决赛、2019-2024OPL职业联赛等各类国内外高级别比赛的赛事组织工作，时至今日樱帆电竞已经完成超过500个游戏项目赛事组织执行工作。2021年公司成立直转播节目制作业务板块，完成了征途全民争霸赛总决赛暨年终盛典、三届永劫无间高校总决赛、剑网3竞技群英赛、DCDC冠军联赛、实况足球世总赛、影之诗联赛、漫威争锋冠军杯、SCS年度总决赛、蛋仔派对高校总决赛、剑网3竞技大师赛等在内的上百个大型项目的直转播节目制作工作。目前在上海拥有包括1个制播中心及5套演播棚在内的1500平专业节目制播场地以及一个技术中心、一个创意中心，专业服务于各类电竞赛事及泛娱乐节目制作。 | D30: 电竞赛事实习导演 | E30: 2 | F30: 大专 | G30: 岗位概述：作为公司导演及创意方向的核心管培生，你将参与到行业细分领域最头部的各项电竞赛事及内容节目的全流程导演工作中。我们希望你具备自主学习、钻研创新、吃苦耐劳的优秀品质和能力，对游戏和电竞内容抱有浓厚兴趣与较高审美。公司会针对管培安排包含培训、考核、轮岗等多样化的培养计划，并对表现优秀者优先招聘录用。一、岗位职责：1.【创意策划】：协助总导演对接产品相关的线上线下活动的前期创意策划，能够根据客户的需求，协助分析赛事或活动举办的底层逻辑；2.【筹备推进】：根据策划方案，协助总导演深化产出流程RD、视觉包装设计等创意落地方案，协助并确保各项产出匹配预期规划，保证项目顺利完成；3.【沟通协作】：协助总导演做好内外部的沟通管理与协调工作。在跨部门协作中，能够帮助总导演做到及时高效精准的信息沟通，保持各部门之间良好持久的协作关系，有效帮助工作推进。熟练掌握英/日/韩等外语书面及口语沟通能力者加分；4.【落地执行】：赛事/活动执行的彩排与直播期间，协助总导演完成现场的执行导演工作；5【复盘总结】：协助总导演对完成项目进行总结复盘，系统化整理与分享经验。二、任职要求:1.大专及以上学历，影视编导、新闻传播、电竞赛事等相关专业优先；2.热爱电子竞技，了解电竞产业，对某一类游戏产品及主流电竞赛事有较深理解，游戏高段位或游戏高时长将为加分项；3.具有较好的时间管理及多任务规划能力，拥有敏锐的洞察力能对市场和客户做出一定判断；4.思维活跃、创意十足、善于表达、逻辑思考能力强、有较好的审美及文案能力，抗压性好，具备平面三维设计、视频后期剪辑能力，熟练AI工具使用者优先；5.实习期间将重点参与格斗类赛道最头部产品的全球顶级赛事筹备和全流程制作。 | H30: 日薪：150-200/天 | I30: =_xlfn.CONCAT(D30,"（学历：",F30," 专业要求：",IF(ISBLANK(M30),"无",M30),"）") -> 电竞赛事实习导演（学历：大专 专业要求：影视编导,新闻传播学类,新闻与传播,新闻传播学） | J30: =LEN(G30) -> 722 | K30: =_xlfn.XLOOKUP(A30,长度要求!A:A,长度要求!E:E) -> 500 | L30: =IF(J30<K30,G30,LEFT(G30,K30)&"……") -> 岗位概述：作为公司导演及创意方向的核心管培生，你将参与到行业细分领域最头部的各项电竞赛事及内容节目的全流程导演工作中。我们希望你具备自主学习、钻研创新、吃苦耐劳的优秀品质和能力，对游戏和电竞内容抱有浓厚兴趣与较高审美。公司会针对管培安排包含培训、考核、轮岗等多样化的培养计划，并对表现优秀者优先招聘录用。一、岗位职责：1.【创意策划】：协助总导演对接产品相关的线上线下活动的前期创意策划，能够根据客户的需求，协助分析赛事或活动举办的底层逻辑；2.【筹备推进】：根据策划方案，协助总导演深化产出流程RD、视觉包装设计等创意落地方案，协助并确保各项产出匹配预期规划，保证项目顺利完成；3.【沟通协作】：协助总导演做好内外部的沟通管理与协调工作。在跨部门协作中，能够帮助总导演做到及时高效精准的信息沟通，保持各部门之间良好持久的协作关系，有效帮助工作推进。熟练掌握英/日/韩等外语书面及口语沟通能力者加分；4.【落地执行】：赛事/活动执行的彩排与直播期间，协助总导演完成现场的执行导演工作；5【复盘总结】：协助总导演对完成项目进行总结复盘，系统化整理与分享经验。二、任职要求:1.大专及以上学历，影视编导、…… | M30: 影视编导,新闻传播学类,新闻与传播,新闻传播学 | N30: =LEN(M30) -> 23 | O30: =IF(ISBLANK(M30),0,COUNTA(_xlfn.TEXTSPLIT(M30,","))) -> 4
A31: =COUNTIF(B:B,B31) -> 2 | B31: 中国电信股份有限公司上海莘闵电信局 | C31: 中国电信股份有限公司上海莘闵电信局坐落于闵行区莘东路199号，简称莘闵电信局。前身为上海市电话局莘闵区局。2000年7月1日，中国电信集团上海市电信公司成立后，更名为上海市电信公司莘闵电信局；2008年3月，更名为中国电信股份有限公司上海莘闵电信局。中国电信股份有限公司上海莘闵电信局提供固定电话、移动通信、宽带互联网接入、互联网电视、卫星通信、信息化应用等泛在网络和综合智能信息服务能力，服务闵行区内各类客户，始终保持区域内通信市场的领先地位。莘闵电信局以党的建设统领企业发展全局，以改革创新为动力，加快推进"网络智能化、业务生态化和运营智慧化"，积极构建"五大业务"生态圈，努力做领先的综合智能信息服务运营商,为闵行区经济发展和网络强国建设做出更大贡献，助推闵行区信息化及经济高速增长。 | D31: 装维见习生 | E31: 30 | F31: 大专 | G31: 电信宽带、固定电话、IPTV等电信业务的安装与故障维修，同时承担客户沟通与网络简单维护任务。 | H31: 日薪：80-150/天 | I31: =_xlfn.CONCAT(D31,"（学历：",F31," 专业要求：",IF(ISBLANK(M31),"无",M31),"）") -> 装维见习生（学历：大专 专业要求：无） | J31: =LEN(G31) -> 46 | K31: =_xlfn.XLOOKUP(A31,长度要求!A:A,长度要求!E:E) -> 500 | L31: =IF(J31<K31,G31,LEFT(G31,K31)&"……") -> 电信宽带、固定电话、IPTV等电信业务的安装与故障维修，同时承担客户沟通与网络简单维护任务。 | N31: =LEN(M31) -> 0 | O31: =IF(ISBLANK(M31),0,COUNTA(_xlfn.TEXTSPLIT(M31,","))) -> 0
A32: =COUNTIF(B:B,B32) -> 4 | B32: 上海樱帆望文化传媒有限公司 | C32: 樱帆电竞成立于2015年8月，以电竞赛事组织策划执行和直转播节目制作为业务核心。赛事组织板块已经完成过2018年雅加达亚运会、2018-2019年WESG全球总决赛、2019-2024OPL职业联赛等各类国内外高级别比赛的赛事组织工作，时至今日樱帆电竞已经完成超过500个游戏项目赛事组织执行工作。2021年公司成立直转播节目制作业务板块，完成了征途全民争霸赛总决赛暨年终盛典、三届永劫无间高校总决赛、剑网3竞技群英赛、DCDC冠军联赛、实况足球世总赛、影之诗联赛、漫威争锋冠军杯、SCS年度总决赛、蛋仔派对高校总决赛、剑网3竞技大师赛等在内的上百个大型项目的直转播节目制作工作。目前在上海拥有包括1个制播中心及5套演播棚在内的1500平专业节目制播场地以及一个技术中心、一个创意中心，专业服务于各类电竞赛事及泛娱乐节目制作。 | D32: 电竞赛事执行 | E32: 2 | F32: 大专 | G32: 一、游戏硬性要求：包括但不限于以下两款游戏，可接受入职之后再熟悉拳皇KOF全系列【1、拳皇KOF全系列（97-15均可），街霸6，铁拳等游戏，以上游戏单产品游戏时长50小时以上】【2、瓦罗兰特，游戏段位要求达到超凡】二、岗位要求：1、有拳皇系列&街霸6等格斗游戏经验的优先；2、有国内城市办赛经验者优先；3、熟练excel、word、PPT等日常办公软件；4、熟悉市场主流游戏的游戏机制和赛事规则；5、具有一定沟通、抗压能力，擅长对接及协助工作；三、任职要求1.专业背景●传媒、广播电视、数字媒体技术、电子竞技等相关专业优先。2.技能要求●具备一定的计算机操作能力，熟悉常用办公软件。●对电竞有浓厚兴趣，了解电竞赛事直播特点。3.态度品质●工作认真负责，细心耐心，有较强的学习能力和团队合作精神。4.学历要求●大专以上学历，26届27届毕业生优先。小贴士：公司比较看重岗位匹配度，同时也致力于挖掘每一位求职者的潜在能力，让大家能在最适合的岗位上发光发热。 | H32: 日薪：150-200/天 | I32: =_xlfn.CONCAT(D32,"（学历：",F32," 专业要求：",IF(ISBLANK(M32),"无",M32),"）") -> 电竞赛事执行（学历：大专 专业要求：体育学类,广播影视节目制作,文化服务类,广告学） | J32: =LEN(G32) -> 427 | K32: =_xlfn.XLOOKUP(A32,长度要求!A:A,长度要求!E:E) -> 500 | L32: =IF(J32<K32,G32,LEFT(G32,K32)&"……") -> 一、游戏硬性要求：包括但不限于以下两款游戏，可接受入职之后再熟悉拳皇KOF全系列【1、拳皇KOF全系列（97-15均可），街霸6，铁拳等游戏，以上游戏单产品游戏时长50小时以上】【2、瓦罗兰特，游戏段位要求达到超凡】二、岗位要求：1、有拳皇系列&街霸6等格斗游戏经验的优先；2、有国内城市办赛经验者优先；3、熟练excel、word、PPT等日常办公软件；4、熟悉市场主流游戏的游戏机制和赛事规则；5、具有一定沟通、抗压能力，擅长对接及协助工作；三、任职要求1.专业背景●传媒、广播电视、数字媒体技术、电子竞技等相关专业优先。2.技能要求●具备一定的计算机操作能力，熟悉常用办公软件。●对电竞有浓厚兴趣，了解电竞赛事直播特点。3.态度品质●工作认真负责，细心耐心，有较强的学习能力和团队合作精神。4.学历要求●大专以上学历，26届27届毕业生优先。小贴士：公司比较看重岗位匹配度，同时也致力于挖掘每一位求职者的潜在能力，让大家能在最适合的岗位上发光发热。 | M32: 体育学类,广播影视节目制作,文化服务类,广告学 | N32: =LEN(M32) -> 23 | O32: =IF(ISBLANK(M32),0,COUNTA(_xlfn.TEXTSPLIT(M32,","))) -> 4
A33: =COUNTIF(B:B,B33) -> 4 | B33: 上海樱帆望文化传媒有限公司 | C33: 樱帆电竞成立于2015年8月，以电竞赛事组织策划执行和直转播节目制作为业务核心。赛事组织板块已经完成过2018年雅加达亚运会、2018-2019年WESG全球总决赛、2019-2024OPL职业联赛等各类国内外高级别比赛的赛事组织工作，时至今日樱帆电竞已经完成超过500个游戏项目赛事组织执行工作。2021年公司成立直转播节目制作业务板块，完成了征途全民争霸赛总决赛暨年终盛典、三届永劫无间高校总决赛、剑网3竞技群英赛、DCDC冠军联赛、实况足球世总赛、影之诗联赛、漫威争锋冠军杯、SCS年度总决赛、蛋仔派对高校总决赛、剑网3竞技大师赛等在内的上百个大型项目的直转播节目制作工作。目前在上海拥有包括1个制播中心及5套演播棚在内的1500平专业节目制播场地以及一个技术中心、一个创意中心，专业服务于各类电竞赛事及泛娱乐节目制作。 | D33: 制片助理 | E33: 2 | F33: 大专 | G33: 任职要求​1、专业不限，对影视、广告等行业的制片工作有兴趣者优先；​2、具备清晰的逻辑思维能力，能够有条理地处理多项事务；​3、做事缜密细致，注重细节，有较强的责任心和执行力；​4、具备良好的沟通表达能力，能与团队成员及外部供应商有效协作；​5、熟练使用办公软件（如Word、Excel等），有一定的数据整理能力。岗位职责​1、制片事务执行：协助制片完成项目中与“吃喝住行”相关的各项预定及执行工作，包括但不限于预订拍摄期间的餐饮、住宿、交通等，确保各项安排准确无误，保障项目顺利推进。​2、验收与记录：负责对项目所需物资、服务等进行验收，并按要求进行拍照记录，确保相关资料的完整性和准确性，为后续工作提供可靠依据。​3、辅助结案制作：在项目结案阶段，积极配合团队完成相关资料的整理、汇总等辅助工作，助力顺利产出制作成果。​4、供应商沟通：与各类供应商保持良好沟通，及时传达需求、反馈问题，协调解决合作过程中的相关事宜，维护稳定的合作关系。​5、报销收集整理：负责收集项目相关的各类报销凭证，按照公司规定进行整理、核对，确保报销信息准确、完整。 | H33: 日薪：150-200/天 | I33: =_xlfn.CONCAT(D33,"（学历：",F33," 专业要求：",IF(ISBLANK(M33),"无",M33),"）") -> 制片助理（学历：大专 专业要求：竞赛组织,新闻与传播,项目管理,文化服务类,广播影视类,广播影视节目制作,广告策划与营销） | J33: =LEN(G33) -> 472 | K33: =_xlfn.XLOOKUP(A33,长度要求!A:A,长度要求!E:E) -> 500 | L33: =IF(J33<K33,G33,LEFT(G33,K33)&"……") -> 任职要求​1、专业不限，对影视、广告等行业的制片工作有兴趣者优先；​2、具备清晰的逻辑思维能力，能够有条理地处理多项事务；​3、做事缜密细致，注重细节，有较强的责任心和执行力；​4、具备良好的沟通表达能力，能与团队成员及外部供应商有效协作；​5、熟练使用办公软件（如Word、Excel等），有一定的数据整理能力。岗位职责​1、制片事务执行：协助制片完成项目中与“吃喝住行”相关的各项预定及执行工作，包括但不限于预订拍摄期间的餐饮、住宿、交通等，确保各项安排准确无误，保障项目顺利推进。​2、验收与记录：负责对项目所需物资、服务等进行验收，并按要求进行拍照记录，确保相关资料的完整性和准确性，为后续工作提供可靠依据。​3、辅助结案制作：在项目结案阶段，积极配合团队完成相关资料的整理、汇总等辅助工作，助力顺利产出制作成果。​4、供应商沟通：与各类供应商保持良好沟通，及时传达需求、反馈问题，协调解决合作过程中的相关事宜，维护稳定的合作关系。​5、报销收集整理：负责收集项目相关的各类报销凭证，按照公司规定进行整理、核对，确保报销信息准确、完整。 | M33: 竞赛组织,新闻与传播,项目管理,文化服务类,广播影视类,广播影视节目制作,广告策划与营销 | N33: =LEN(M33) -> 44 | O33: =IF(ISBLANK(M33),0,COUNTA(_xlfn.TEXTSPLIT(M33,","))) -> 7
A34: =COUNTIF(B:B,B34) -> 2 | B34: 上海羊鑫布艺有限公司 | C34: 上海羊鑫布艺有限公司是海派旗袍与新中式文化创新的时尚企业作为上海海派旗袍文化促进会副会长单位,公司以"致知青花"系列为代表,融合传统制衣工艺与现代设计,打造独具东方韵味的高级定制服饰。产品屡获长三角旗袍设计大赛银奖等殊荣,创始人杨玉娟女士获“东方时尚工匠”称号。公司通过时尚闪秀、文化展览等多元化形式,致力于传承和发展海派旗袍文化,推动传统服饰艺术的现代表达与创新发展。 | D34: 打样纸板师 | E34: 1 | F34: 大专 | G34: 【岗位职责】负责服装款式的打板与制版工作：根据设计师提供的效果图、设计稿或样衣，精准制作纸样（含裁剪版、工艺版），确保版型符合设计风格与人体工学。样衣跟进与调整：配合样衣车间完成首件样衣制作，参与样衣试穿评审，根据试穿反馈（如尺寸偏差、版型舒适度）优化纸样，直至样衣合格。工艺文件输出：整理打板数据，制定详细的制版工艺说明（如缝份、缩率、面料特性适配方案），为生产车间提供清晰的技术指导。版型库管理：建立并维护公司版型数据库，分类归档不同款式、尺码的纸样文件，便于后续款式复用与优化。跨部门协作：与设计师、采购部（确认面料特性）、生产部（解决生产中的版型问题）高效配合，确保打板-制版-生产流程顺畅。【任职要求】学历与经验：中专及以上学历，服装相关专业（如服装工程、服装设计），1-3年及以上服装打板/制版经验（应届生可投递助理岗，需熟悉基础打板逻辑）。核心技能：熟练掌握手工打板技巧，能独立完成从净版到毛版的制作；精通制版软件（如富怡、ET、格柏Gerber等），可高效进行数字化制版与纸样修改；了解不同面料特性（如棉、丝、针织、弹力面料）对版型的影响，能针对性调整打板方案；熟悉服装号型标准（如GB/T1335、欧码、美码等），可根据目标市场适配尺码版型。能力素质：细节敏感度强，能精准把控版型尺寸误差（如±0.5cm内）；沟通能力佳，能清晰理解设计需求并反馈技术可行性；有责任心，能按时完成打板任务，配合紧急款式的开发需求 | H34: 月薪：5K-6K | I34: =_xlfn.CONCAT(D34,"（学历：",F34," 专业要求：",IF(ISBLANK(M34),"无",M34),"）") -> 打样纸板师（学历：大专 专业要求：无） | J34: =LEN(G34) -> 614 | K34: =_xlfn.XLOOKUP(A34,长度要求!A:A,长度要求!E:E) -> 500 | L34: =IF(J34<K34,G34,LEFT(G34,K34)&"……") -> 【岗位职责】负责服装款式的打板与制版工作：根据设计师提供的效果图、设计稿或样衣，精准制作纸样（含裁剪版、工艺版），确保版型符合设计风格与人体工学。样衣跟进与调整：配合样衣车间完成首件样衣制作，参与样衣试穿评审，根据试穿反馈（如尺寸偏差、版型舒适度）优化纸样，直至样衣合格。工艺文件输出：整理打板数据，制定详细的制版工艺说明（如缝份、缩率、面料特性适配方案），为生产车间提供清晰的技术指导。版型库管理：建立并维护公司版型数据库，分类归档不同款式、尺码的纸样文件，便于后续款式复用与优化。跨部门协作：与设计师、采购部（确认面料特性）、生产部（解决生产中的版型问题）高效配合，确保打板-制版-生产流程顺畅。【任职要求】学历与经验：中专及以上学历，服装相关专业（如服装工程、服装设计），1-3年及以上服装打板/制版经验（应届生可投递助理岗，需熟悉基础打板逻辑）。核心技能：熟练掌握手工打板技巧，能独立完成从净版到毛版的制作；精通制版软件（如富怡、ET、格柏Gerber等），可高效进行数字化制版与纸样修改；了解不同面料特性（如棉、丝、针织、弹力面料）对版型的影响，能针对性调整打板方案；熟悉服装号型标准（如G…… | N34: =LEN(M34) -> 0 | O34: =IF(ISBLANK(M34),0,COUNTA(_xlfn.TEXTSPLIT(M34,","))) -> 0
A35: =COUNTIF(B:B,B35) -> 4 | B35: 上海天安轴承有限公司 | C35: 上海天安轴承有限公司为上海电气集团旗下上海集优机械有限公司的全资企业，位于上海市闵行区莘庄工业园区银都路4399号，具有60多年的生产历史。公司专业生产具有高精度、高转速、高灵敏度、低噪音、长寿命的微型轴承，并对轴承产品进行技术开发和产品售后服务。产品广泛运用于航空航天、工业装备、汽车医疗等行业，性能达到国际领先水平。近几年公司大力支持国家航天事业，已为“天宫一号”、“神舟五号”、“神州六号”、“神舟七号”、“神州八号”和“绕月探测工程”成功配套，获得了国家有关部门的多次嘉奖。 | D35: 数控操作 | E35: 2 | F35: 大专 | G35: 1、按作业指导书及设备操作规程，正确操作和保养数控机床2、对数控机床进行加工编程、线切割3、做好加工零件的自查，确保加工产品合格率 | H35: 月薪：5K-7K | I35: =_xlfn.CONCAT(D35,"（学历：",F35," 专业要求：",IF(ISBLANK(M35),"无",M35),"）") -> 数控操作（学历：大专 专业要求：无） | J35: =LEN(G35) -> 65 | K35: =_xlfn.XLOOKUP(A35,长度要求!A:A,长度要求!E:E) -> 500 | L35: =IF(J35<K35,G35,LEFT(G35,K35)&"……") -> 1、按作业指导书及设备操作规程，正确操作和保养数控机床2、对数控机床进行加工编程、线切割3、做好加工零件的自查，确保加工产品合格率 | N35: =LEN(M35) -> 0 | O35: =IF(ISBLANK(M35),0,COUNTA(_xlfn.TEXTSPLIT(M35,","))) -> 0
A36: =COUNTIF(B:B,B36) -> 1 | B36: 上海特金信息科技有限公司 | C36: 上海特金创立于2003年，是国家级高新技术企业、国家级专精特新“小巨人”企业、上海市“专精特新”企业，20余年深耕无线电感知和频谱大数据分析技术，致力于提供可信赖的低空安全管控解决方案，在无人机预案、预警、识别、定位、追踪及处置方面处于业界领军地位，是国内将TDOA网格化无人机管控技术进行产品化和大规模商用的发起者。特金拥有一百多项核心知识产权，深度参与国标、行标、团标的标准制定，荣获国际电联ITUTelecomWorld全球最佳创新奖。特金无人机探测定位管制系统服务于建党百周年庆及70周年国庆首都核心区，杭州亚运会、成都大运会、央视春晚等大型活动低空安全保障，被誉为“低空防御专家，家国和平卫士”。 | D36: 助理产品工程师 | E36: 7 | F36: 大专 | G36: 岗位职责：1、通过相关培训能够快速适应生产作业，保证每个产品都是按照工艺要求生产；2、经过培训严格按照工艺要求熟练掌握产品组装、调试、测试；3、严格执行上级领导指派的工作任务；4、严格执行生产安全管理制度；5、遵守6S现场规章制度，保持生产线标准化工作环境；6、负责日常设备问题排查维修并输出维修报告。任职资格：1、机械，机电，电子，电气，通讯，无线电专业等工学专业；2、要求大专学历，应届毕业生或实习生；3、掌握基础电路、机械、钳工专业知识，会简单编程，熟练使用办公软件；4、能够接受不定时加班、户外测试，有驾驶证优先；5、有机械证书或者电工证优先；6、为人正直有较强的团队协助精神、勤奋好学、积极向上、有敬业精神，无不良嗜好。7、能尽快上岗者优先。 | H36: 月薪：5K-8K | I36: =_xlfn.CONCAT(D36,"（学历：",F36," 专业要求：",IF(ISBLANK(M36),"无",M36),"）") -> 助理产品工程师（学历：大专 专业要求：无） | J36: =LEN(G36) -> 326 | K36: =_xlfn.XLOOKUP(A36,长度要求!A:A,长度要求!E:E) -> 500 | L36: =IF(J36<K36,G36,LEFT(G36,K36)&"……") -> 岗位职责：1、通过相关培训能够快速适应生产作业，保证每个产品都是按照工艺要求生产；2、经过培训严格按照工艺要求熟练掌握产品组装、调试、测试；3、严格执行上级领导指派的工作任务；4、严格执行生产安全管理制度；5、遵守6S现场规章制度，保持生产线标准化工作环境；6、负责日常设备问题排查维修并输出维修报告。任职资格：1、机械，机电，电子，电气，通讯，无线电专业等工学专业；2、要求大专学历，应届毕业生或实习生；3、掌握基础电路、机械、钳工专业知识，会简单编程，熟练使用办公软件；4、能够接受不定时加班、户外测试，有驾驶证优先；5、有机械证书或者电工证优先；6、为人正直有较强的团队协助精神、勤奋好学、积极向上、有敬业精神，无不良嗜好。7、能尽快上岗者优先。 | N36: =LEN(M36) -> 0 | O36: =IF(ISBLANK(M36),0,COUNTA(_xlfn.TEXTSPLIT(M36,","))) -> 0
A37: =COUNTIF(B:B,B37) -> 4 | B37: 上海天安轴承有限公司 | C37: 上海天安轴承有限公司为上海电气集团旗下上海集优机械有限公司的全资企业，位于上海市闵行区莘庄工业园区银都路4399号，具有60多年的生产历史。公司专业生产具有高精度、高转速、高灵敏度、低噪音、长寿命的微型轴承，并对轴承产品进行技术开发和产品售后服务。产品广泛运用于航空航天、工业装备、汽车医疗等行业，性能达到国际领先水平。近几年公司大力支持国家航天事业，已为“天宫一号”、“神舟五号”、“神州六号”、“神舟七号”、“神州八号”和“绕月探测工程”成功配套，获得了国家有关部门的多次嘉奖。 | D37: 电气维修 | E37: 2 | F37: 大专 | G37: 负责公司电气故障的排除；对公司内用电的分配、设计及用电管理工作；监督检查变电所管理制度的执行情况及备件管理工作 | H37: 月薪：5K-7K | I37: =_xlfn.CONCAT(D37,"（学历：",F37," 专业要求：",IF(ISBLANK(M37),"无",M37),"）") -> 电气维修（学历：大专 专业要求：无） | J37: =LEN(G37) -> 55 | K37: =_xlfn.XLOOKUP(A37,长度要求!A:A,长度要求!E:E) -> 500 | L37: =IF(J37<K37,G37,LEFT(G37,K37)&"……") -> 负责公司电气故障的排除；对公司内用电的分配、设计及用电管理工作；监督检查变电所管理制度的执行情况及备件管理工作 | N37: =LEN(M37) -> 0 | O37: =IF(ISBLANK(M37),0,COUNTA(_xlfn.TEXTSPLIT(M37,","))) -> 0
A38: =COUNTIF(B:B,B38) -> 2 | B38: 上海科瑞物业管理发展有限公司 | C38: “和我们共创无限可能的未来”上海科瑞物业管理发展有限公司，成立于2002年1月18日，注册资金5000万元。公司致力于成为“成为现代物业服务专业管家”品牌企业，服务于超高层建筑、城市综合体、办公楼、大型住宅、公众项目；以及提供大中小学校区管理、酒店管理和物业顾问等服务。科瑞物业崇尚现代物业管理理念，坚持以人为本、生态平衡的管理服务本质，追求高标准管理、细节化服务、规范化收费、可持续发展，以“一切围绕和谐、创造和谐而奋斗！”作为企业口号既企业管理方针，维护社会、业主、企业三方利益。我们的实力：1）上海市物业管理协会副会长单位；2）上海市物业服务综合百强企业排名第三3）上海市物业管理数量领先企业、物业管理面积领先企业（住宅类、非居类、办公类、学校类）TOP104）进入（外）城市个数领先企业、营业收入领先企业、轨道交通收入领先企业、净利润领先企业、员工总数领先企业TOP105）上市公司的成员企业，从东北长春吉林到南部广东佛山，从西北内蒙古到东部上海都有我们科瑞的足迹你有梦想吗？即使面临现实的社会，残酷的生活，你想在此情形下继续维持梦想吗？你想在繁重的工作之余还有诗和远方吗？你想拥有自由的发展空间吗？加入我们，我们能提供你想要的，你梦想的，与科瑞共同创造未来。 | D38: 智能建筑工程实习生 | E38: 10 | F38: 大专 | G38: 通过参与智能建筑工程全流程（设计辅助、现场实施、调试配合、文档整理等）工作，帮助实习生掌握智能建筑系统（如楼宇自控、安防监控、综合布线等）的基本原理与实际应用，熟悉工程现场管理流程，培养工程实践能力与问题解决意识，为未来从事智能建筑相关工作奠定基础。 | H38: 日薪：80-150/天 | I38: =_xlfn.CONCAT(D38,"（学历：",F38," 专业要求：",IF(ISBLANK(M38),"无",M38),"）") -> 智能建筑工程实习生（学历：大专 专业要求：建筑智能化工程技术） | J38: =LEN(G38) -> 125 | K38: =_xlfn.XLOOKUP(A38,长度要求!A:A,长度要求!E:E) -> 500 | L38: =IF(J38<K38,G38,LEFT(G38,K38)&"……") -> 通过参与智能建筑工程全流程（设计辅助、现场实施、调试配合、文档整理等）工作，帮助实习生掌握智能建筑系统（如楼宇自控、安防监控、综合布线等）的基本原理与实际应用，熟悉工程现场管理流程，培养工程实践能力与问题解决意识，为未来从事智能建筑相关工作奠定基础。 | M38: 建筑智能化工程技术 | N38: =LEN(M38) -> 9 | O38: =IF(ISBLANK(M38),0,COUNTA(_xlfn.TEXTSPLIT(M38,","))) -> 1
A39: =COUNTIF(B:B,B39) -> 4 | B39: 上海天安轴承有限公司 | C39: 上海天安轴承有限公司为上海电气集团旗下上海集优机械有限公司的全资企业，位于上海市闵行区莘庄工业园区银都路4399号，具有60多年的生产历史。公司专业生产具有高精度、高转速、高灵敏度、低噪音、长寿命的微型轴承，并对轴承产品进行技术开发和产品售后服务。产品广泛运用于航空航天、工业装备、汽车医疗等行业，性能达到国际领先水平。近几年公司大力支持国家航天事业，已为“天宫一号”、“神舟五号”、“神州六号”、“神舟七号”、“神州八号”和“绕月探测工程”成功配套，获得了国家有关部门的多次嘉奖。 | D39: 设备维修 | E39: 2 | F39: 大专 | G39: 对设备的机械、液压、气动系统的故障、磨损进行维修，确保生产；对设备进行点检、保养工作负责设备的日常报表填写 | H39: 月薪：5K-7K | I39: =_xlfn.CONCAT(D39,"（学历：",F39," 专业要求：",IF(ISBLANK(M39),"无",M39),"）") -> 设备维修（学历：大专 专业要求：无） | J39: =LEN(G39) -> 53 | K39: =_xlfn.XLOOKUP(A39,长度要求!A:A,长度要求!E:E) -> 500 | L39: =IF(J39<K39,G39,LEFT(G39,K39)&"……") -> 对设备的机械、液压、气动系统的故障、磨损进行维修，确保生产；对设备进行点检、保养工作负责设备的日常报表填写 | N39: =LEN(M39) -> 0 | O39: =IF(ISBLANK(M39),0,COUNTA(_xlfn.TEXTSPLIT(M39,","))) -> 0
A40: =COUNTIF(B:B,B40) -> 2 | B40: 图萌（上海）科技有限公司 | C40: 图萌（上海）科技有限公司倡导“科技融合，创新共赢”的理念，专注于新媒体+XR领域的数字技术和内容研发，在人工智能时代背景下，致力于AIGC内容生成式人才的培养，涵盖虚拟现实、数字媒体技术、动漫设计、广播电视编导、节目制作、新闻采编与制作、新媒体艺术、艺术设计、广告学、计算机等领域。作为长三角文旅产业联盟会员单位、教育部职教工场项目白名单企业，图萌科技拥有计算机软件著作权登记证书、上海电影电视技术学会会员单位、上海高等职业学校校企合作联盟单位等资质，并具备AIGC课程研发与授课实战经验，以及上海多媒体行业产教融合专委会成员单位身份。取得高新科技企业、双软企业资质，并通过ISO9001质量管理体系认证，重合同守信用企业、科技型中小企业、专精特新企业资质。图萌科技提供面向AIGC+专业条件下的教育解决方案，基于图智AIGC教学资源平台和云端AIGC工具平台，落地人才培养方案、课程建设实施、实验实训建设、师资培训服务、教辅教材开发、赛事指导支持和职业证书认证等服务。 | D40: 平面设计 | E40: 2 | F40: 大专 | G40: 岗位职责1、负责公司宣传材料、册页等的设计与整合。2、精通PS、AI等设计软件。3、参与设计讨论，和业务团队共同创建用户界面，跟踪设计效果，提出设计优化方案。4、良好的团队精神，工作踏实稳定。岗位要求1、全日制大专或以上学历，艺术设计类相关专业毕业。2、有实习经验者优先，能独立完成设计方案。3、会使用CAD做平面布局图者优先。4、会渲染三维效果图者优先。 | H40: 日薪：80-200/天 | I40: =_xlfn.CONCAT(D40,"（学历：",F40," 专业要求：",IF(ISBLANK(M40),"无",M40),"）") -> 平面设计（学历：大专 专业要求：视觉传达设计） | J40: =LEN(G40) -> 178 | K40: =_xlfn.XLOOKUP(A40,长度要求!A:A,长度要求!E:E) -> 500 | L40: =IF(J40<K40,G40,LEFT(G40,K40)&"……") -> 岗位职责1、负责公司宣传材料、册页等的设计与整合。2、精通PS、AI等设计软件。3、参与设计讨论，和业务团队共同创建用户界面，跟踪设计效果，提出设计优化方案。4、良好的团队精神，工作踏实稳定。岗位要求1、全日制大专或以上学历，艺术设计类相关专业毕业。2、有实习经验者优先，能独立完成设计方案。3、会使用CAD做平面布局图者优先。4、会渲染三维效果图者优先。 | M40: 视觉传达设计 | N40: =LEN(M40) -> 6 | O40: =IF(ISBLANK(M40),0,COUNTA(_xlfn.TEXTSPLIT(M40,","))) -> 1
...

Sheet 展区展位
A1: 名称 | B1: 展区 | C1: 展位
A2: 上海无线电设备研究所 | B2: A机械/制造/能源 | C2: A01
A3: 上海航天控制技术研究所 | B3: A机械/制造/能源 | C3: A02
A4: 上海航天电子通讯设备研究所 | B4: A机械/制造/能源 | C4: A03
A5: 上海卫星装备研究所 | B5: A机械/制造/能源 | C5: A04
A6: 上海航天精密机械研究所 | B6: A机械/制造/能源 | C6: A05
A7: 上海空间电源研究所 | B7: A机械/制造/能源 | C7: A06
A8: 上海新力动力设备研究所 | B8: A机械/制造/能源 | C8: A07
A9: 航天八院一四九厂 | B9: A机械/制造/能源 | C9: A08
A10: 上海中航光电子有限公司 | B10: A机械/制造/能源 | C10: A09
A11: 上海三菱电梯有限公司安装维修分公司 | B11: A机械/制造/能源 | C11: A10
A12: 上海飒智智能科技有限公司 | B12: A机械/制造/能源 | C12: A11
... A127: 上海笛申文化发展有限公司 | B127: F综合 | C127: F11

Sheet 长度要求
A1: 岗位数 | B1: 企业简介长度 | C1: 岗位介绍长度 | D1: 简介最长 | E1: 介绍最长
A2: 1 | B2: 200 | C2: 500 | D2: 200 | E2: 500
A3: 2 | B3: 200 | C3: 500 | D3: 200 | E3: 500
A4: 3 | B4: 200 | C4: 500 | D4: 200 | E4: 500
A5: 4 | B5: 200 | C5: 500 | D5: 200 | E5: 500
A6: 5 | B6: 200 | C6: 500 | D6: 200 | E6: 500
A7: 6 | B7: 200 | C7: 500 | D7: 200 | E7: 500
A8: 7 | B8: 200 | C8: 500 | D8: 200 | E8: 500
A9: 8 | B9: 200 | C9: 500 | D9: 200 | E9: 500
A10: 9 | B10: 200 | C10: 500 | D10: 200 | E10: 500
A11: 10 | B11: 200 | C11: 500 | D11: 200 | E11: 500
A12: 11 | B12: 200 | C12: 500 | D12: 200 | E12: 500
A13: 12 | B13: 200 | C13: 500 | D13: 200 | E13: 500
... A31: 30 | B31: 204 | C31: 500 | D31: 200 | E31: 500

Sheet 企业简介提取
A1: 岗位数量 | B1: 企业名称 | C1: 企业简介 | D1: 长度 | E1: 长度要求 | F1: 截取后内容
A2: =COUNTIF(B:B,B2) -> 4 | B2: 上海光通信有限公司 | C2: 上海光通信有限公司（英文名 Shanghai GTX Semiconductor Co., Ltd，下称“GTX”），成立于1988年，于2022年初转型进入集成电路制造领域。 | D2: =LEN(C2) -> 88 | E2: =_xlfn.XLOOKUP(A2,长度要求!A:A,长度要求!D:D) -> 200 | F2: =IF(D2<E2,C2,LEFT(C2,E2)&"……") -> 上海光通信有限公司（英文名 Shanghai GTX Semiconductor Co., Ltd，下称“GTX”），成立于1988年，于2022年初转型进入集成电路制造领域。
A3: =COUNTIF(B:B,B3) -> 6 | B3: 上海新皋实业有限公司 | C3: 新皋实业成立于2013年初，总部位于上海虹桥机场毗邻的明谷科技园，公司在智能家居领域率先投入智能家居控制系统的项目研发、生产及销售。获得软件专利著作权十多项，企业获得国家商标局认证商标： 《新皋》《XINGAO》《艾登堡》《ATNBO》等品牌，并推出真正适合国内外用户的智能影音系列产品。自主研发新皋XINGAO智能影院中控系统及艾登堡ATNBO家庭影院系列产品,深受行业专业人士好评。 新皋实业是上海闵行区就业促进中心审核认定的大学生实习基地，常年招收在校大学生实习实践，上海闵行地区户籍大学生或闵行地区高校学生优先录取，实习享受上海市闵行区人社局补贴。 | D3: =LEN(C3) -> 291 | E3: =_xlfn.XLOOKUP(A3,长度要求!A:A,长度要求!D:D) -> 200 | F3: =IF(D3<E3,C3,LEFT(C3,E3)&"……") -> 新皋实业成立于2013年初，总部位于上海虹桥机场毗邻的明谷科技园，公司在智能家居领域率先投入智能家居控制系统的项目研发、生产及销售。获得软件专利著作权十多项，企业获得国家商标局认证商标： 《新皋》《XINGAO》《艾登堡》《ATNBO》等品牌，并推出真正适合国内外用户的智能影音系列产品。自主研发新皋XINGAO智能影院中控系统及艾登堡ATNBO家庭影院系列产品,深受行业专业人士好评。……
A4: =COUNTIF(B:B,B4) -> 6 | B4: 上海新皋实业有限公司 | C4: 新皋实业成立于2013年初，总部位于上海虹桥机场毗邻的明谷科技园，公司在智能家居领域率先投入智能家居控制系统的项目研发、生产及销售。获得软件专利著作权十多项，企业获得国家商标局认证商标： 《新皋》《XINGAO》《艾登堡》《ATNBO》等品牌，并推出真正适合国内外用户的智能影音系列产品。自主研发新皋XINGAO智能影院中控系统及艾登堡ATNBO家庭影院系列产品,深受行业专业人士好评。 新皋实业是上海闵行区就业促进中心审核认定的大学生实习基地，常年招收在校大学生实习实践，上海闵行地区户籍大学生或闵行地区高校学生优先录取，实习享受上海市闵行区人社局补贴。 | D4: =LEN(C4) -> 291 | E4: =_xlfn.XLOOKUP(A4,长度要求!A:A,长度要求!D:D) -> 200 | F4: =IF(D4<E4,C4,LEFT(C4,E4)&"……") -> 新皋实业成立于2013年初，总部位于上海虹桥机场毗邻的明谷科技园，公司在智能家居领域率先投入智能家居控制系统的项目研发、生产及销售。获得软件专利著作权十多项，企业获得国家商标局认证商标： 《新皋》《XINGAO》《艾登堡》《ATNBO》等品牌，并推出真正适合国内外用户的智能影音系列产品。自主研发新皋XINGAO智能影院中控系统及艾登堡ATNBO家庭影院系列产品,深受行业专业人士好评。……
A5: =COUNTIF(B:B,B5) -> 2 | B5: 上海德辰汽车销售有限公司 | C5: 上海德辰汽车销售公司是北方一大型汽车经销商集团在上海新投资创立的 一汽大众奥迪品牌 4S 店。超越了传统豪华汽车 4S 店的概念，实际具备品牌体 验、车型展示、新车销售、售后服务、二手车置换等多种功能，完备的设施以 及周到的服务一应俱全，体现出国际豪华品牌全球统一的服务水准。 该城市展厅坐落于闵行区颛桥地区（颛兴东路 1280 弄 3 号）。地铁、轻轨 均可到达，交通便捷。地址：颛兴东路 1280 弄 3 号。总占地面积 11455 平方 米。上下共有三层，展厅面积 4168 平方米，销售展示分两层，有超过多个标准 汽车展位，大厅设有人性化的自动扶梯；屋顶设置顶楼停车厂，日接待能力超 过 100 台。简洁明快的建筑风格，落地玻璃和透明天窗的结合使整个展厅最大 限度地充满阳光和自然气息，充分体现了人性与科技的完美结合，展现奥迪品 牌的超凡卓越和豪华尊贵，修理车间面积 7287 平方米，共有多个汽车维修工 位，技术人员有 40 人，分为机修、电工、钣金、喷漆区，布局合理，设备先 进。突出强调“买车修车到德辰，诚信舒心更放心”的服务理念。也是每个德 辰员工的座右铭。我们以完善的硬件设施、周到的人性化服务迎接您的光临。 背景介绍 上海德辰的股东旗下共拥有多家 4S 店，其中在长春、嘉兴、宁波销售一汽 奥迪、一汽马自达、一汽丰田等知名品牌汽车。 企业文化 上海德辰奉行“务实、诚信、进取、激情、团队精神、服务意识”的企业 文化；在选人、用人、育人上：以具竞争力的薪酬吸引人才、以完善的培训体 系培养人才，以强烈的业绩导向、快速的晋升和广阔的发展空间开发人才。 | D5: =LEN(C5) -> 697 | E5: =_xlfn.XLOOKUP(A5,长度要求!A:A,长度要求!D:D) -> 200 | F5: =IF(D5<E5,C5,LEFT(C5,E5)&"……") -> 上海德辰汽车销售公司是北方一大型汽车经销商集团在上海新投资创立的 一汽大众奥迪品牌 4S 店。超越了传统豪华汽车 4S 店的概念，实际具备品牌体 验、车型展示、新车销售、售后服务、二手车置换等多种功能，完备的设施以 及周到的服务一应俱全，体现出国际豪华品牌全球统一的服务水准。 该城市展厅坐落于闵行区颛桥地区（颛兴东路 1280 弄 3 号）。地铁、轻轨 均可到达，交通便捷。地址：颛兴东路 ……
A6: =COUNTIF(B:B,B6) -> 1 | B6: 上海市黄浦区西凌第一幼儿园 | C6: 西凌第一幼儿园是一所上海市示范性幼儿园、上海市文明单位。地处黄浦区西藏南路，园内幼儿活动场地充裕，环境优美，四季绿化常青，阳光充足，是“上海市花园单位”。我园积极探索围棋与游戏融合的探索，秉持“以人为本，民主和谐，快乐发展”办园宗旨和 “以棋养德、以棋怡情、以棋明理、以棋启智”的教育理念，深受幼儿与家长的喜欢。西凌第一幼儿园已成为孩子们游戏、学习、生活的乐园。 | D6: =LEN(C6) -> 184 | E6: =_xlfn.XLOOKUP(A6,长度要求!A:A,长度要求!D:D) -> 200 | F6: =IF(D6<E6,C6,LEFT(C6,E6)&"……") -> 西凌第一幼儿园是一所上海市示范性幼儿园、上海市文明单位。地处黄浦区西藏南路，园内幼儿活动场地充裕，环境优美，四季绿化常青，阳光充足，是“上海市花园单位”。我园积极探索围棋与游戏融合的探索，秉持“以人为本，民主和谐，快乐发展”办园宗旨和 “以棋养德、以棋怡情、以棋明理、以棋启智”的教育理念，深受幼儿与家长的喜欢。西凌第一幼儿园已成为孩子们游戏、学习、生活的乐园。
A7: =COUNTIF(B:B,B7) -> 6 | B7: 上海新皋实业有限公司 | C7: 新皋实业成立于2013年初，总部位于上海虹桥机场毗邻的明谷科技园，公司在智能家居领域率先投入智能家居控制系统的项目研发、生产及销售。获得软件专利著作权十多项，企业获得国家商标局认证商标： 《新皋》《XINGAO》《艾登堡》《ATNBO》等品牌，并推出真正适合国内外用户的智能影音系列产品。自主研发新皋XINGAO智能影院中控系统及艾登堡ATNBO家庭影院系列产品,深受行业专业人士好评。 新皋实业是上海闵行区就业促进中心审核认定的大学生实习基地，常年招收在校大学生实习实践，上海闵行地区户籍大学生或闵行地区高校学生优先录取，实习享受上海市闵行区人社局补贴。 | D7: =LEN(C7) -> 291 | E7: =_xlfn.XLOOKUP(A7,长度要求!A:A,长度要求!D:D) -> 200 | F7: =IF(D7<E7,C7,LEFT(C7,E7)&"……") -> 新皋实业成立于2013年初，总部位于上海虹桥机场毗邻的明谷科技园，公司在智能家居领域率先投入智能家居控制系统的项目研发、生产及销售。获得软件专利著作权十多项，企业获得国家商标局认证商标： 《新皋》《XINGAO》《艾登堡》《ATNBO》等品牌，并推出真正适合国内外用户的智能影音系列产品。自主研发新皋XINGAO智能影院中控系统及艾登堡ATNBO家庭影院系列产品,深受行业专业人士好评。……
A8: =COUNTIF(B:B,B8) -> 6 | B8: 上海新皋实业有限公司 | C8: 新皋实业成立于2013年初，总部位于上海虹桥机场毗邻的明谷科技园，公司在智能家居领域率先投入智能家居控制系统的项目研发、生产及销售。获得软件专利著作权十多项，企业获得国家商标局认证商标： 《新皋》《XINGAO》《艾登堡》《ATNBO》等品牌，并推出真正适合国内外用户的智能影音系列产品。自主研发新皋XINGAO智能影院中控系统及艾登堡ATNBO家庭影院系列产品,深受行业专业人士好评。 新皋实业是上海闵行区就业促进中心审核认定的大学生实习基地，常年招收在校大学生实习实践，上海闵行地区户籍大学生或闵行地区高校学生优先录取，实习享受上海市闵行区人社局补贴。 | D8: =LEN(C8) -> 291 | E8: =_xlfn.XLOOKUP(A8,长度要求!A:A,长度要求!D:D) -> 200 | F8: =IF(D8<E8,C8,LEFT(C8,E8)&"……") -> 新皋实业成立于2013年初，总部位于上海虹桥机场毗邻的明谷科技园，公司在智能家居领域率先投入智能家居控制系统的项目研发、生产及销售。获得软件专利著作权十多项，企业获得国家商标局认证商标： 《新皋》《XINGAO》《艾登堡》《ATNBO》等品牌，并推出真正适合国内外用户的智能影音系列产品。自主研发新皋XINGAO智能影院中控系统及艾登堡ATNBO家庭影院系列产品,深受行业专业人士好评。……
A9: =COUNTIF(B:B,B9) -> 6 | B9: 上海新皋实业有限公司 | C9: 新皋实业成立于2013年初，总部位于上海虹桥机场毗邻的明谷科技园，公司在智能家居领域率先投入智能家居控制系统的项目研发、生产及销售。获得软件专利著作权十多项，企业获得国家商标局认证商标： 《新皋》《XINGAO》《艾登堡》《ATNBO》等品牌，并推出真正适合国内外用户的智能影音系列产品。自主研发新皋XINGAO智能影院中控系统及艾登堡ATNBO家庭影院系列产品,深受行业专业人士好评。 新皋实业是上海闵行区就业促进中心审核认定的大学生实习基地，常年招收在校大学生实习实践，上海闵行地区户籍大学生或闵行地区高校学生优先录取，实习享受上海市闵行区人社局补贴。 | D9: =LEN(C9) -> 291 | E9: =_xlfn.XLOOKUP(A9,长度要求!A:A,长度要求!D:D) -> 200 | F9: =IF(D9<E9,C9,LEFT(C9,E9)&"……") -> 新皋实业成立于2013年初，总部位于上海虹桥机场毗邻的明谷科技园，公司在智能家居领域率先投入智能家居控制系统的项目研发、生产及销售。获得软件专利著作权十多项，企业获得国家商标局认证商标： 《新皋》《XINGAO》《艾登堡》《ATNBO》等品牌，并推出真正适合国内外用户的智能影音系列产品。自主研发新皋XINGAO智能影院中控系统及艾登堡ATNBO家庭影院系列产品,深受行业专业人士好评。……
A10: =COUNTIF(B:B,B10) -> 6 | B10: 上海新皋实业有限公司 | C10: 新皋实业成立于2013年初，总部位于上海虹桥机场毗邻的明谷科技园，公司在智能家居领域率先投入智能家居控制系统的项目研发、生产及销售。获得软件专利著作权十多项，企业获得国家商标局认证商标： 《新皋》《XINGAO》《艾登堡》《ATNBO》等品牌，并推出真正适合国内外用户的智能影音系列产品。自主研发新皋XINGAO智能影院中控系统及艾登堡ATNBO家庭影院系列产品,深受行业专业人士好评。 新皋实业是上海闵行区就业促进中心审核认定的大学生实习基地，常年招收在校大学生实习实践，上海闵行地区户籍大学生或闵行地区高校学生优先录取，实习享受上海市闵行区人社局补贴。 | D10: =LEN(C10) -> 291 | E10: =_xlfn.XLOOKUP(A10,长度要求!A:A,长度要求!D:D) -> 200 | F10: =IF(D10<E10,C10,LEFT(C10,E10)&"……") -> 新皋实业成立于2013年初，总部位于上海虹桥机场毗邻的明谷科技园，公司在智能家居领域率先投入智能家居控制系统的项目研发、生产及销售。获得软件专利著作权十多项，企业获得国家商标局认证商标： 《新皋》《XINGAO》《艾登堡》《ATNBO》等品牌，并推出真正适合国内外用户的智能影音系列产品。自主研发新皋XINGAO智能影院中控系统及艾登堡ATNBO家庭影院系列产品,深受行业专业人士好评。……
A11: =COUNTIF(B:B,B11) -> 2 | B11: 上海网鱼酒店管理有限公司 | C11: 网鱼创始于1998年，从诞生之初就秉承不断创新的理念，致力于打造多人游戏空间。截至2020年12月31日，网鱼全球会员数超2000万，服务覆盖国内外106个城市。全球拥有超1000家门店，年服务人次超3000万，iG战队倾情代言，是深受全球玩家喜爱的聚玩圣地。2021年推出“网鱼电竞酒店”，正式进军电竞酒店行业，打造跨品类、跨业态、跨平台的综合娱乐型品牌，践行“给用户美好的体验”。 | D11: =LEN(C11) -> 192 | E11: =_xlfn.XLOOKUP(A11,长度要求!A:A,长度要求!D:D) -> 200 | F11: =IF(D11<E11,C11,LEFT(C11,E11)&"……") -> 网鱼创始于1998年，从诞生之初就秉承不断创新的理念，致力于打造多人游戏空间。截至2020年12月31日，网鱼全球会员数超2000万，服务覆盖国内外106个城市。全球拥有超1000家门店，年服务人次超3000万，iG战队倾情代言，是深受全球玩家喜爱的聚玩圣地。2021年推出“网鱼电竞酒店”，正式进军电竞酒店行业，打造跨品类、跨业态、跨平台的综合娱乐型品牌，践行“给用户美好的体验”。
A12: =COUNTIF(B:B,B12) -> 2 | B12: 上海网鱼酒店管理有限公司 | C12: 网鱼创始于1998年，从诞生之初就秉承不断创新的理念，致力于打造多人游戏空间。截至2020年12月31日，网鱼全球会员数超2000万，服务覆盖国内外106个城市。全球拥有超1000家门店，年服务人次超3000万，iG战队倾情代言，是深受全球玩家喜爱的聚玩圣地。2021年推出“网鱼电竞酒店”，正式进军电竞酒店行业，打造跨品类、跨业态、跨平台的综合娱乐型品牌，践行“给用户美好的体验”。 | D12: =LEN(C12) -> 192 | E12: =_xlfn.XLOOKUP(A12,长度要求!A:A,长度要求!D:D) -> 200 | F12: =IF(D12<E12,C12,LEFT(C12,E12)&"……") -> 网鱼创始于1998年，从诞生之初就秉承不断创新的理念，致力于打造多人游戏空间。截至2020年12月31日，网鱼全球会员数超2000万，服务覆盖国内外106个城市。全球拥有超1000家门店，年服务人次超3000万，iG战队倾情代言，是深受全球玩家喜爱的聚玩圣地。2021年推出“网鱼电竞酒店”，正式进军电竞酒店行业，打造跨品类、跨业态、跨平台的综合娱乐型品牌，践行“给用户美好的体验”。
A13: =COUNTIF(B:B,B13) -> 4 | B13: 珍岛信息技术（上海）股份有限公司 | C13: 珍岛信息技术（上海）股份有限公司（简称珍岛集团，股票代码02556.HK）是中国最大的营销及销售SaaS公司，也是最早推出 T-force 营销领域大模型的公司，最早推出 AI-Agentforce 中台的公司，聚焦数字化与智能化，基于人工智能、大数据技术，是专注数字化智能营销的SaaS服务提供商，于2024年在香港上市。 | D13: =LEN(C13) -> 162 | E13: =_xlfn.XLOOKUP(A13,长度要求!A:A,长度要求!D:D) -> 200 | F13: =IF(D13<E13,C13,LEFT(C13,E13)&"……") -> 珍岛信息技术（上海）股份有限公司（简称珍岛集团，股票代码02556.HK）是中国最大的营销及销售SaaS公司，也是最早推出 T-force 营销领域大模型的公司，最早推出 AI-Agentforce 中台的公司，聚焦数字化与智能化，基于人工智能、大数据技术，是专注数字化智能营销的SaaS服务提供商，于2024年在香港上市。
... A363: =COUNTIF(B:B,B363) -> 3 | B363: 中信泰富（上海）物业管理有限公司 | C363: 中信泰富（上海）物业管理有限公司于2004年在上海注册成立。中信泰富物业以中信集团创始人、前国家副主席荣毅仁先生所倡导的“遵纪守法、作风正派、实事求是、开拓创新、谦虚谨慎、团结互助、勤勉奋发、雷厉风行”三十二字作为企业文化建设的指导方针；以“品质源自于细节的关怀”作为作风特征，突出“规范、周到、务实、高效”的服务宗旨，努力创建具有“国际水准、中国特色”的一流物业管理企业。 | D363: =LEN(C363) -> 194 | E363: =_xlfn.XLOOKUP(A363,长度要求!A:A,长度要求!D:D) -> 200 | F363: =IF(D363<E363,C363,LEFT(C363,E363)&"……") -> 中信泰富（上海）物业管理有限公司于2004年在上海注册成立。中信泰富物业以中信集团创始人、前国家副主席荣毅仁先生所倡导的“遵纪守法、作风正派、实事求是、开拓创新、谦虚谨慎、团结互助、勤勉奋发、雷厉风行”三十二字作为企业文化建设的指导方针；以“品质源自于细节的关怀”作为作风特征，突出“规范、周到、务实、高效”的服务宗旨，努力创建具有“国际水准、中国特色”的一流物业管理企业。

Sheet 岗位1
A1: 展区 | B1: 展位 | C1: 单位名称 | D1: 单位简介 | E1: 职位1标题 | F1: 职位1jd | H1: 单位简介 | I1: 职位1jd
A2: =_xlfn.XLOOKUP(C2,展区展位!A:A,展区展位!B:B) -> D教育/传媒/电竞 | B2: =_xlfn.XLOOKUP(C2,展区展位!A:A,展区展位!C:C) -> D06 | C2: 上海市黄浦区西凌第一幼儿园 | D2: =_xlfn.XLOOKUP(C2,企业简介提取!B:B,企业简介提取!F:F) -> 西凌第一幼儿园是一所上海市示范性幼儿园、上海市文明单位。地处黄浦区西藏南路，园内幼儿活动场地充裕，环境优美，四季绿化常青，阳光充足，是“上海市花园单位”。我园积极探索围棋与游戏融合的探索，秉持“以人为本，民主和谐，快乐发展”办园宗旨和 “以棋养德、以棋怡情、以棋明理、以棋启智”的教育理念，深受幼儿与家长的喜欢。西凌第一幼儿园已成为孩子们游戏、学习、生活的乐园。 | E2: =INDEX(_xlfn._xlws.FILTER(报名明细!$I:$I,报名明细!$B:$B=$C2),1) -> 保育员（学历：初中及以下 专业要求：学前教育,卫生教育） | F2: =INDEX(_xlfn._xlws.FILTER(报名明细!$L:$L,报名明细!$B:$B=$C2),1) -> 具有良好师德，爱孩子，有正确的儿童观具备保育专业知识与技能 | H2: 西凌第一幼儿园是一所上海市示范性幼儿园、上海市文明单位。地处黄浦区西藏南路，园内幼儿活动场地充裕，环境优美，四季绿化常青，阳光充足，是“上海市花园单位”。我园积极探索围棋与游戏融合的探索，秉持“以人为本，民主和谐，快乐发展”办园宗旨和“以棋养德、以棋怡情、以棋明理、以棋启智”的教育理念，深受幼儿与家长的喜欢。西凌第一幼儿园已成为孩子们游戏、学习、生活的乐园。 | I2: 具有良好师德，爱孩子，有正确的儿童观具备保育专业知识与技能
A3: =_xlfn.XLOOKUP(C3,展区展位!A:A,展区展位!B:B) -> E城市运营与技术服务 | B3: =_xlfn.XLOOKUP(C3,展区展位!A:A,展区展位!C:C) -> E01 | C3: 上海世博中心有限公司 | D3: =_xlfn.XLOOKUP(C3,企业简介提取!B:B,企业简介提取!F:F) -> 上海世博中心，作为上海市机关事务管理局下属国有企业，同样具备了举办展览、会议、活动以及房屋租赁的功能，与上展中心在浦江两岸形成东西呼应的两座上海标志性建筑。上海世博中心以成为世界级的会议中心为目标。世博会期间，其承担了庆典、交流、贵宾接待、新闻发布和指挥运营等重要任务。世博会后，已转型成为大型高规格国际会议的重要场所，一方面承担政务服务功能，成为上海市“两会”及其他政务性会议的重要举办场所；另一方…… | E3: =INDEX(_xlfn._xlws.FILTER(报名明细!$I:$I,报名明细!$B:$B=$C3),1) -> 会展接待服务（学历：初中及以下 专业要求：无） | F3: =INDEX(_xlfn._xlws.FILTER(报名明细!$L:$L,报名明细!$B:$B=$C3),1) -> 1.女：身高1.65米以上，专业不限；2.品貌端正、无纹身、对工作有责任心，能吃苦耐劳；3.按照客户要求布置好会场，做好会前的准备工作；4.做好会中接待工作，确保会议有序进行；5.本岗位可招收实习生；6.完成上级安排的其他工作。 | H3: 上海世博中心，作为上海市机关事务管理局下属国有企业，同样具备了举办展览、会议、活动以及房屋租赁的功能，与上展中心在浦江两岸形成东西呼应的两座上海标志性建筑。上海世博中心以成为世界级的会议中心为目标。世博会期间，其承担了庆典、交流、贵宾接待、新闻发布和指挥运营等重要任务。世博会后，已转型成为大型高规格国际会议的重要场所，一方面承担政务服务功能，成为上海市“两会”及其他政务性会议的重要举办场所；另一方面还要承载社会功能，对市场和社会开放，以其会议、展览、活动（宴会）等专业功能形成核心竞争力，充分展示上海国际大都会形象，提升上海城市的综合竞争力。 | I3: 1.女：身高1.65米以上，专业不限；2.品貌端正、无纹身、对工作有责任心，能吃苦耐劳；3.按照客户要求布置好会场，做好会前的准备工作；4.做好会中接待工作，确保会议有序进行；5.本岗位可招收实习生；6.完成上级安排的其他工作。
